<?xml version="1.0" ?>
<!-- =================================================================================== -->
<!-- |    This document was autogenerated by xacro from panda_arm_hand_on_segway.urdf.xacro | -->
<!-- |    EDITING THIS FILE BY HAND IS NOT RECOMMENDED                                 | -->
<!-- =================================================================================== -->
<robot name="panda" xmlns:xacro="http://www.ros.org/wiki/xacro">
  <gazebo>
    <plugin filename="libgazebo_ros_control.so" name="gazebo_ros_control">
      <robotNamespace>/</robotNamespace>
    </plugin>
  </gazebo>
  <!-- Base link is the center of the robot's chassis between the motors projected on the ground -->
  <link name="base_link"/>
  <joint name="base_chassis_joint" type="fixed">
    <origin rpy="0 0 0" xyz="0 0 0.15801795"/>
    <parent link="base_link"/>
    <child link="base_chassis_link"/>
  </joint>
  <link name="base_chassis_link">
    <visual>
      <geometry>
        <mesh filename="package://segway_description/meshes/visual/std_gearbox_chassis.dae"/>
      </geometry>
    </visual>
  </link>
  <link name="inertial_collision_link">
    <inertial>
      <mass value="36.914402"/>
      <origin xyz="-0.043407 0.000037 0.060079"/>
      <inertia ixx="1.182744" ixy="0.017957" ixz="-0.077476" iyx="0.017957" iyy="0.538664" iyz="0.000018" izx="-0.077476" izy="0.000018" izz="1.240229"/>
    </inertial>
    <collision>
      <geometry>
        <mesh filename="package://segway_description/meshes/collision/RMP210_chassis_collision.stl"/>
      </geometry>
    </collision>
  </link>
  <joint name="inertial_collision_joint" type="fixed">
    <parent link="base_chassis_link"/>
    <child link="inertial_collision_link"/>
  </joint>
  <joint name="left_spacer_joint" type="fixed">
    <origin rpy="0 0 0" xyz="0 0.19582 0.00665015"/>
    <parent link="base_chassis_link"/>
    <child link="left_spacer_link"/>
  </joint>
  <link name="left_spacer_link">
    <visual>
      <geometry>
        <mesh filename="package://segway_description/meshes/visual/single_spacer.dae"/>
      </geometry>
    </visual>
  </link>
  <joint name="right_spacer_joint" type="fixed">
    <origin rpy="0 0 3.14159" xyz="0 -0.19582 0.00665015"/>
    <parent link="base_chassis_link"/>
    <child link="right_spacer_link"/>
  </joint>
  <link name="right_spacer_link">
    <visual>
      <geometry>
        <mesh filename="package://segway_description/meshes/visual/single_spacer.dae"/>
      </geometry>
    </visual>
  </link>
  <joint name="mcu_1_battery_joint" type="fixed">
    <origin rpy="0 0 0" xyz="-0.09298 0 0"/>
    <parent link="base_chassis_link"/>
    <child link="mcu_1_battery_link"/>
  </joint>
  <link name="mcu_1_battery_link">
    <visual>
      <geometry>
        <mesh filename="package://segway_description/meshes/visual/battery.dae"/>
      </geometry>
    </visual>
  </link>
  <joint name="ui_box_mount_joint" type="fixed">
    <origin rpy="0 0 0" xyz="-0.1016 0 0.1273"/>
    <parent link="base_chassis_link"/>
    <child link="ui_box_mount_link"/>
  </joint>
  <link name="ui_box_mount_link">
    <visual>
      <geometry>
        <mesh filename="package://segway_description/meshes/visual/ui_box_spacer_mount.dae"/>
      </geometry>
    </visual>
  </link>
  <joint name="ui_box_joint" type="fixed">
    <origin rpy="0 0 0" xyz="-0.1016 0 0.1273"/>
    <parent link="base_chassis_link"/>
    <child link="ui_box_link"/>
  </joint>
  <link name="ui_box_link">
    <visual>
      <geometry>
        <mesh filename="package://segway_description/meshes/visual/ui_box.dae"/>
      </geometry>
    </visual>
  </link>
  <joint name="aux_battery_joint" type="fixed">
    <origin rpy="3.14159 0 0" xyz="-0.07845 0 0.1932753"/>
    <parent link="base_chassis_link"/>
    <child link="aux_battery_link"/>
  </joint>
  <link name="aux_battery_link">
    <inertial>
      <mass value="60"/>
    </inertial>
    <visual>
      <geometry>
        <mesh filename="package://segway_description/meshes/visual/battery.dae"/>
      </geometry>
    </visual>
  </link>
  <link name="left_wheel_link">
    <inertial>
      <mass value="4.195729"/>
      <origin xyz="0 0 0"/>
      <inertia ixx="0.063680" ixy="0.000000" ixz="0.000000" iyx="0.000000" iyy="0.121410" iyz="0.000000" izx="0.000000" izy="0.000000" izz="0.063680"/>
    </inertial>
    <visual>
      <origin rpy="0 0 0.0" xyz="0 0 0"/>
      <geometry>
        <mesh filename="package://segway_description/meshes/visual/i2_wheel.dae"/>
      </geometry>
    </visual>
    <collision>
      <origin rpy="1.570795 0 0" xyz="0 0 0"/>
      <geometry>
        <cylinder length="0.092249" radius="0.2405681"/>
      </geometry>
    </collision>
  </link>
  <gazebo reference="left_wheel_link">
    <mu1 value="10.0"/>
    <mu2 value="10.0"/>
    <kp value="10000000.0"/>
    <kd value="10.0"/>
    <fdir1 value="1 0 0"/>
    <minDepth>0.003</minDepth>
  </gazebo>
  <joint name="left_wheel" type="continuous">
    <parent link="base_chassis_link"/>
    <child link="left_wheel_link"/>
    <origin rpy="0 0 0" xyz="0 0.2711955 0.08255015"/>
    <axis rpy="0 0 0" xyz="0 1 0"/>
  </joint>
  <transmission name="left_wheel_trans" type="SimpleTransmission">
    <type>transmission_interface/SimpleTransmission</type>
    <actuator name="left_wheel_motor">
      <mechanicalReduction>1</mechanicalReduction>
    </actuator>
    <joint name="left_wheel">
      <hardwareInterface>VelocityJointInterface</hardwareInterface>
    </joint>
  </transmission>
  <link name="right_wheel_link">
    <inertial>
      <mass value="4.195729"/>
      <origin xyz="0 0 0"/>
      <inertia ixx="0.063680" ixy="0.000000" ixz="0.000000" iyx="0.000000" iyy="0.121410" iyz="0.000000" izx="0.000000" izy="0.000000" izz="0.063680"/>
    </inertial>
    <visual>
      <origin rpy="0 0 3.14159" xyz="0 0 0"/>
      <geometry>
        <mesh filename="package://segway_description/meshes/visual/i2_wheel.dae"/>
      </geometry>
    </visual>
    <collision>
      <origin rpy="1.570795 0 0" xyz="0 0 0"/>
      <geometry>
        <cylinder length="0.092249" radius="0.2405681"/>
      </geometry>
    </collision>
  </link>
  <gazebo reference="right_wheel_link">
    <mu1 value="10.0"/>
    <mu2 value="10.0"/>
    <kp value="10000000.0"/>
    <kd value="10.0"/>
    <fdir1 value="1 0 0"/>
    <minDepth>0.003</minDepth>
  </gazebo>
  <joint name="right_wheel" type="continuous">
    <parent link="base_chassis_link"/>
    <child link="right_wheel_link"/>
    <origin rpy="0 0 0" xyz="0 -0.2711955 0.08255015"/>
    <axis rpy="0 0 0" xyz="0 1 0"/>
  </joint>
  <transmission name="right_wheel_trans" type="SimpleTransmission">
    <type>transmission_interface/SimpleTransmission</type>
    <actuator name="right_wheel_motor">
      <mechanicalReduction>1</mechanicalReduction>
    </actuator>
    <joint name="right_wheel">
      <hardwareInterface>VelocityJointInterface</hardwareInterface>
    </joint>
  </transmission>
  <joint name="rear_caster_plate_joint" type="fixed">
    <origin rpy="0 0 0" xyz="-0.31472057 0 0.02425235"/>
    <parent link="base_chassis_link"/>
    <child link="rear_caster_plate_link"/>
  </joint>
  <link name="rear_caster_plate_link">
    <inertial>
      <mass value="4.487241"/>
      <origin xyz="0.027375 0 0.016101"/>
      <inertia ixx="0.070527" ixy="0.000000" ixz="-0.001013" iyx="0.000000" iyy="0.010678" iyz="0.000000" izx="-0.001013" izy="0.000000" izz="0.078313"/>
    </inertial>
    <visual>
      <geometry>
        <mesh filename="package://segway_description/meshes/visual/caster_plate.dae"/>
      </geometry>
    </visual>
    <collision>
      <geometry>
        <mesh filename="package://segway_description/meshes/collision/caster_plate_collision.stl"/>
      </geometry>
    </collision>
  </link>
  <link name="rear_caster_swivel_link">
    <inertial>
      <mass value="0.579519"/>
      <origin xyz="-0.020596 0.000280 -0.055367"/>
      <inertia ixx="0.001361" ixy="-0.000003" ixz="0.000347" iyx="-0.000003" iyy="0.001287" iyz="-0.000010" izx="0.000347" izy="-0.000010" izz="0.000632"/>
    </inertial>
    <visual>
      <geometry>
        <mesh filename="package://segway_description/meshes/visual/caster_bracket.dae"/>
      </geometry>
    </visual>
    <collision>
      <geometry>
        <mesh filename="package://segway_description/meshes/collision/caster_bracket_collision.stl"/>
      </geometry>
    </collision>
  </link>
  <gazebo reference="rear_caster_swivel_link">
    <mu1 value="100.0"/>
    <mu2 value="100.0"/>
    <kp value="10000000.0"/>
    <kd value="1.0"/>
  </gazebo>
  <joint name="rear_caster_swivel" type="continuous">
    <parent link="rear_caster_plate_link"/>
    <child link="rear_caster_swivel_link"/>
    <!--xacro:insert_block name="joint_pose"/-->
    <axis xyz="0 0 1"/>
    <anchor xyz="0 0 0"/>
    <limit effort="0.0" velocity="1000"/>
    <dynamics damping="0.7"/>
  </joint>
  <transmission name="rear_caster_swivel_trans" type="SimpleTransmission">
    <type>transmission_interface/SimpleTransmission</type>
    <joint name="rear_caster_swivel">
      <hardwareInterface>EffortJointInterface</hardwareInterface>
    </joint>
    <actuator name="rear_caster_swivel_motor">
      <hardwareInterface>EffortJointInterface</hardwareInterface>
      <mechanicalReduction>1</mechanicalReduction>
    </actuator>
  </transmission>
  <link name="rear_caster_wheel_link">
    <inertial>
      <mass value="1.25"/>
      <origin xyz="0 0 0"/>
      <inertia ixx="0.02888" ixy="0.000000" ixz="0.000000" iyx="0.000000" iyy="0.02888" iyz="0.000000" izx="0.000000" izy="0.000000" izz="0.02888"/>
    </inertial>
    <visual>
      <geometry>
        <mesh filename="package://segway_description/meshes/visual/caster_wheel.dae"/>
      </geometry>
    </visual>
    <collision>
      <origin rpy="1.570795 0 0" xyz="0 0 0"/>
      <geometry>
        <cylinder length="0.050" radius="0.0762"/>
      </geometry>
    </collision>
  </link>
  <gazebo reference="rear_caster_wheel_link">
    <mu1 value="100.0"/>
    <mu2 value="100.0"/>
    <kp value="10000000.0"/>
    <kd value="10.0"/>
    <fdir1 value="1 0 0"/>
    <minDepth>0.003</minDepth>
  </gazebo>
  <joint name="rear_caster_wheel" type="continuous">
    <parent link="rear_caster_swivel_link"/>
    <child link="rear_caster_wheel_link"/>
    <origin rpy="0 0 0" xyz="-0.03782 0 -0.10608"/>
    <axis xyz="0 1 0"/>
    <anchor xyz="-0.03782 0 -0.10608"/>
    <limit effort="0.0" velocity="1000"/>
    <dynamics damping="0.2"/>
  </joint>
  <transmission name="rear_caster_wheel_trans" type="SimpleTransmission">
    <type>transmission_interface/SimpleTransmission</type>
    <joint name="rear_caster_wheel">
      <hardwareInterface>EffortJointInterface</hardwareInterface>
    </joint>
    <actuator name="rear_caster_wheel_motor">
      <hardwareInterface>EffortJointInterface</hardwareInterface>
      <mechanicalReduction>1</mechanicalReduction>
    </actuator>
  </transmission>
  <joint name="front_caster_plate_joint" type="fixed">
    <origin rpy="0 0 3.14159" xyz="0.31472057 0 0.02425235"/>
    <parent link="base_chassis_link"/>
    <child link="front_caster_plate_link"/>
  </joint>
  <link name="front_caster_plate_link">
    <inertial>
      <mass value="4.487241"/>
      <origin xyz="0.027375 0 0.016101"/>
      <inertia ixx="0.070527" ixy="0.000000" ixz="-0.001013" iyx="0.000000" iyy="0.010678" iyz="0.000000" izx="-0.001013" izy="0.000000" izz="0.078313"/>
    </inertial>
    <visual>
      <geometry>
        <mesh filename="package://segway_description/meshes/visual/caster_plate.dae"/>
      </geometry>
    </visual>
    <collision>
      <geometry>
        <mesh filename="package://segway_description/meshes/collision/caster_plate_collision.stl"/>
      </geometry>
    </collision>
  </link>
  <link name="front_caster_swivel_link">
    <inertial>
      <mass value="0.579519"/>
      <origin xyz="-0.020596 0.000280 -0.055367"/>
      <inertia ixx="0.001361" ixy="-0.000003" ixz="0.000347" iyx="-0.000003" iyy="0.001287" iyz="-0.000010" izx="0.000347" izy="-0.000010" izz="0.000632"/>
    </inertial>
    <visual>
      <geometry>
        <mesh filename="package://segway_description/meshes/visual/caster_bracket.dae"/>
      </geometry>
    </visual>
    <collision>
      <geometry>
        <mesh filename="package://segway_description/meshes/collision/caster_bracket_collision.stl"/>
      </geometry>
    </collision>
  </link>
  <gazebo reference="front_caster_swivel_link">
    <mu1 value="100.0"/>
    <mu2 value="100.0"/>
    <kp value="10000000.0"/>
    <kd value="1.0"/>
  </gazebo>
  <joint name="front_caster_swivel" type="continuous">
    <parent link="front_caster_plate_link"/>
    <child link="front_caster_swivel_link"/>
    <!--xacro:insert_block name="joint_pose"/-->
    <axis xyz="0 0 1"/>
    <anchor xyz="0 0 0"/>
    <limit effort="0.0" velocity="1000"/>
    <dynamics damping="0.7"/>
  </joint>
  <transmission name="front_caster_swivel_trans" type="SimpleTransmission">
    <type>transmission_interface/SimpleTransmission</type>
    <joint name="front_caster_swivel">
      <hardwareInterface>EffortJointInterface</hardwareInterface>
    </joint>
    <actuator name="front_caster_swivel_motor">
      <hardwareInterface>EffortJointInterface</hardwareInterface>
      <mechanicalReduction>1</mechanicalReduction>
    </actuator>
  </transmission>
  <link name="front_caster_wheel_link">
    <inertial>
      <mass value="1.25"/>
      <origin xyz="0 0 0"/>
      <inertia ixx="0.02888" ixy="0.000000" ixz="0.000000" iyx="0.000000" iyy="0.02888" iyz="0.000000" izx="0.000000" izy="0.000000" izz="0.02888"/>
    </inertial>
    <visual>
      <geometry>
        <mesh filename="package://segway_description/meshes/visual/caster_wheel.dae"/>
      </geometry>
    </visual>
    <collision>
      <origin rpy="1.570795 0 0" xyz="0 0 0"/>
      <geometry>
        <cylinder length="0.050" radius="0.0762"/>
      </geometry>
    </collision>
  </link>
  <gazebo reference="front_caster_wheel_link">
    <mu1 value="100.0"/>
    <mu2 value="100.0"/>
    <kp value="10000000.0"/>
    <kd value="10.0"/>
    <fdir1 value="1 0 0"/>
    <minDepth>0.003</minDepth>
  </gazebo>
  <joint name="front_caster_wheel" type="continuous">
    <parent link="front_caster_swivel_link"/>
    <child link="front_caster_wheel_link"/>
    <origin rpy="0 0 0" xyz="-0.03782 0 -0.10608"/>
    <axis xyz="0 1 0"/>
    <anchor xyz="-0.03782 0 -0.10608"/>
    <limit effort="0.0" velocity="1000"/>
    <dynamics damping="0.2"/>
  </joint>
  <transmission name="front_caster_wheel_trans" type="SimpleTransmission">
    <type>transmission_interface/SimpleTransmission</type>
    <joint name="front_caster_wheel">
      <hardwareInterface>EffortJointInterface</hardwareInterface>
    </joint>
    <actuator name="front_caster_wheel_motor">
      <hardwareInterface>EffortJointInterface</hardwareInterface>
      <mechanicalReduction>1</mechanicalReduction>
    </actuator>
  </transmission>
  <joint name="panda_joint_base_link" type="fixed">
    <parent link="base_link"/>
    <child link="panda_link0"/>
    <origin rpy="0 0 0" xyz="0 0 0.6"/>
  </joint>
  <link name="panda_link0">
    <visual>
      <geometry>
        <mesh filename="package://franka_description/meshes/visual/link0.dae"/>
      </geometry>
    </visual>
    <collision>
      <geometry>
        <mesh filename="package://franka_description/meshes/collision/link0.stl"/>
      </geometry>
    </collision>
    <inertial>
      <origin rpy="0 0 0" xyz="0 0 0"/>
      <mass value="2.8142028896"/>
      <inertia ixx="0.0129886979" ixy="0.0" ixz="0.0" iyy="0.0165355284" iyz="0" izz="0.0203311636"/>
    </inertial>
  </link>
  <link name="panda_link1">
    <visual>
      <geometry>
        <mesh filename="package://franka_description/meshes/visual/link1.dae"/>
      </geometry>
    </visual>
    <collision>
      <geometry>
        <mesh filename="package://franka_description/meshes/collision/link1.stl"/>
      </geometry>
    </collision>
    <inertial>
      <origin rpy="0 0 0" xyz="0 0 0"/>
      <mass value="2.3599995791"/>
      <inertia ixx="0.0186863903" ixy="0.0" ixz="0.0" iyy="0.0143789874" iyz="0" izz="0.00906812"/>
    </inertial>
  </link>
  <joint name="panda_joint1" type="revolute">
    <safety_controller k_position="100.0" k_velocity="40.0" soft_lower_limit="-2.8973" soft_upper_limit="2.8973"/>
    <origin rpy="0 0 0" xyz="0 0 0.333"/>
    <parent link="panda_link0"/>
    <child link="panda_link1"/>
    <axis xyz="0 0 1"/>
    <limit effort="87" lower="-2.8973" upper="2.8973" velocity="2.1750"/>
  </joint>
  <link name="panda_link2">
    <visual>
      <geometry>
        <mesh filename="package://franka_description/meshes/visual/link2.dae"/>
      </geometry>
    </visual>
    <collision>
      <geometry>
        <mesh filename="package://franka_description/meshes/collision/link2.stl"/>
      </geometry>
    </collision>
    <inertial>
      <origin rpy="0 0 0" xyz="0 0 0"/>
      <mass value="2.379518833"/>
      <inertia ixx="0.0190388734" ixy="0.0" ixz="0.0" iyy="0.0091429124" iyz="0" izz="0.014697537"/>
    </inertial>
  </link>
  <joint name="panda_joint2" type="revolute">
    <safety_controller k_position="100.0" k_velocity="40.0" soft_lower_limit="-1.7628" soft_upper_limit="1.7628"/>
    <origin rpy="-1.57079632679 0 0" xyz="0 0 0"/>
    <parent link="panda_link1"/>
    <child link="panda_link2"/>
    <axis xyz="0 0 1"/>
    <limit effort="87" lower="-1.7628" upper="1.7628" velocity="2.1750"/>
  </joint>
  <link name="panda_link3">
    <visual>
      <geometry>
        <mesh filename="package://franka_description/meshes/visual/link3.dae"/>
      </geometry>
    </visual>
    <collision>
      <geometry>
        <mesh filename="package://franka_description/meshes/collision/link3.stl"/>
      </geometry>
    </collision>
    <inertial>
      <origin rpy="0 0 0" xyz="0 0 0"/>
      <mass value="2.6498823337"/>
      <inertia ixx="0.0129300178" ixy="0.0" ixz="0.0" iyy="0.0150242121" iyz="0" izz="0.0142734598"/>
    </inertial>
  </link>
  <joint name="panda_joint3" type="revolute">
    <safety_controller k_position="100.0" k_velocity="40.0" soft_lower_limit="-2.8973" soft_upper_limit="2.8973"/>
    <origin rpy="1.57079632679 0 0" xyz="0 -0.316 0"/>
    <parent link="panda_link2"/>
    <child link="panda_link3"/>
    <axis xyz="0 0 1"/>
    <limit effort="87" lower="-2.8973" upper="2.8973" velocity="2.1750"/>
  </joint>
  <link name="panda_link4">
    <visual>
      <geometry>
        <mesh filename="package://franka_description/meshes/visual/link4.dae"/>
      </geometry>
    </visual>
    <collision>
      <geometry>
        <mesh filename="package://franka_description/meshes/collision/link4.stl"/>
      </geometry>
    </collision>
    <inertial>
      <origin rpy="0 0 0" xyz="0 0 0"/>
      <mass value="2.6948018744"/>
      <inertia ixx="0.0133874611" ixy="0.0" ixz="0.0" iyy="0.014514325" iyz="0" izz="0.0155175551"/>
    </inertial>
  </link>
  <joint name="panda_joint4" type="revolute">
    <safety_controller k_position="100.0" k_velocity="40.0" soft_lower_limit="-3.0718" soft_upper_limit="-0.0698"/>
    <origin rpy="1.57079632679 0 0" xyz="0.0825 0 0"/>
    <parent link="panda_link3"/>
    <child link="panda_link4"/>
    <axis xyz="0 0 1"/>
    <limit effort="87" lower="-3.0718" upper="-0.0698" velocity="2.1750"/>
  </joint>
  <link name="panda_link5">
    <visual>
      <geometry>
        <mesh filename="package://franka_description/meshes/visual/link5.dae"/>
      </geometry>
    </visual>
    <collision>
      <geometry>
        <mesh filename="package://franka_description/meshes/collision/link5.stl"/>
      </geometry>
    </collision>
    <inertial>
      <origin rpy="0 0 0" xyz="0 0 0"/>
      <mass value="2.9812816864"/>
      <inertia ixx="0.0325565705" ixy="0.0" ixz="0.0" iyy="0.0270660472" iyz="0" izz="0.0115023375"/>
    </inertial>
  </link>
  <joint name="panda_joint5" type="revolute">
    <safety_controller k_position="100.0" k_velocity="40.0" soft_lower_limit="-2.8973" soft_upper_limit="2.8973"/>
    <origin rpy="-1.57079632679 0 0" xyz="-0.0825 0.384 0"/>
    <parent link="panda_link4"/>
    <child link="panda_link5"/>
    <axis xyz="0 0 1"/>
    <limit effort="12" lower="-2.8973" upper="2.8973" velocity="2.6100"/>
  </joint>
  <link name="panda_link6">
    <visual>
      <geometry>
        <mesh filename="package://franka_description/meshes/visual/link6.dae"/>
      </geometry>
    </visual>
    <collision>
      <geometry>
        <mesh filename="package://franka_description/meshes/collision/link6.stl"/>
      </geometry>
    </collision>
    <inertial>
      <origin rpy="0 0 0" xyz="0 0 0"/>
      <mass value="1.1285806309"/>
      <inertia ixx="0.0026052565" ixy="0.0" ixz="0.0" iyy="0.0039897229" iyz="0" izz="0.0047048591"/>
    </inertial>
  </link>
  <joint name="panda_joint6" type="revolute">
    <safety_controller k_position="100.0" k_velocity="40.0" soft_lower_limit="-0.0175" soft_upper_limit="3.7525"/>
    <origin rpy="1.57079632679 0 0" xyz="0 0 0"/>
    <parent link="panda_link5"/>
    <child link="panda_link6"/>
    <axis xyz="0 0 1"/>
    <limit effort="12" lower="-0.0175" upper="3.7525" velocity="2.6100"/>
  </joint>
  <link name="panda_link7">
    <visual>
      <geometry>
        <mesh filename="package://franka_description/meshes/visual/link7.dae"/>
      </geometry>
    </visual>
    <collision>
      <geometry>
        <mesh filename="package://franka_description/meshes/collision/link7.stl"/>
      </geometry>
    </collision>
    <inertial>
      <origin rpy="0 0 0" xyz="0 0 0"/>
      <mass value="0.4052912465"/>
      <inertia ixx="0.0006316592" ixy="0.0" ixz="0.0" iyy="0.0006319639" iyz="0" izz="0.0010607721"/>
    </inertial>
  </link>
  <joint name="panda_joint7" type="revolute">
    <safety_controller k_position="100.0" k_velocity="40.0" soft_lower_limit="-2.8973" soft_upper_limit="2.8973"/>
    <origin rpy="1.57079632679 0 0" xyz="0.088 0 0"/>
    <parent link="panda_link6"/>
    <child link="panda_link7"/>
    <axis xyz="0 0 1"/>
    <limit effort="12" lower="-2.8973" upper="2.8973" velocity="2.6100"/>
  </joint>
  <link name="panda_link8"/>
  <joint name="panda_joint8" type="fixed">
    <origin rpy="0 0 0" xyz="0 0 0.107"/>
    <parent link="panda_link7"/>
    <child link="panda_link8"/>
    <axis xyz="0 0 0"/>
  </joint>
  <joint name="panda_hand_joint" type="fixed">
    <parent link="panda_link8"/>
    <child link="panda_hand"/>
    <origin rpy="0 0 -0.785398163397" xyz="0 0 0"/>
  </joint>
  <link name="panda_hand">
    <visual>
      <geometry>
        <mesh filename="package://franka_description/meshes/visual/hand.dae"/>
      </geometry>
    </visual>
    <collision>
      <geometry>
        <mesh filename="package://franka_description/meshes/collision/hand.stl"/>
      </geometry>
    </collision>
    <inertial>
      <origin rpy="0 0 0" xyz="0 0 0"/>
      <mass value="0.5583304799"/>
      <inertia ixx="0.0023394448" ixy="0.0" ixz="0.0" iyy="0.0005782786" iyz="0" izz="0.0021310296"/>
    </inertial>
  </link>
  <link name="panda_leftfinger">
    <visual>
      <geometry>
        <mesh filename="package://franka_description/meshes/visual/finger.dae"/>
      </geometry>
    </visual>
    <collision>
      <geometry>
        <mesh filename="package://franka_description/meshes/collision/finger.stl"/>
      </geometry>
    </collision>
    <inertial>
      <origin rpy="0 0 0" xyz="0 0 0"/>
      <mass value="0.0140552232"/>
      <inertia ixx="4.20413082650939E-06" ixy="0.0" ixz="0.0" iyy="3.90263687466755E-06" iyz="0" izz="1.33474964199095E-06"/>
    </inertial>
  </link>
  <link name="panda_rightfinger">
    <visual>
      <origin rpy="0 0 3.14159265359" xyz="0 0 0"/>
      <geometry>
        <mesh filename="package://franka_description/meshes/visual/finger.dae"/>
      </geometry>
    </visual>
    <collision>
      <origin rpy="0 0 3.14159265359" xyz="0 0 0"/>
      <geometry>
        <mesh filename="package://franka_description/meshes/collision/finger.stl"/>
      </geometry>
    </collision>
    <inertial>
      <origin rpy="0 0 0" xyz="0 0 0"/>
      <mass value="0.0140552232"/>
      <inertia ixx="4.20413082650939E-06" ixy="0.0" ixz="0.0" iyy="3.90263687466755E-06" iyz="0" izz="1.33474964199095E-06"/>
    </inertial>
  </link>
  <joint name="panda_finger_joint1" type="prismatic">
    <parent link="panda_hand"/>
    <child link="panda_leftfinger"/>
    <origin rpy="0 0 0" xyz="0 0 0.0584"/>
    <axis xyz="0 1 0"/>
    <limit effort="20" lower="0.0" upper="0.04" velocity="0.2"/>
  </joint>
  <joint name="panda_finger_joint2" type="prismatic">
    <parent link="panda_hand"/>
    <child link="panda_rightfinger"/>
    <origin rpy="0 0 0" xyz="0 0 0.0584"/>
    <axis xyz="0 -1 0"/>
    <limit effort="20" lower="0.0" upper="0.04" velocity="0.2"/>
    <mimic joint="panda_finger_joint1"/>
  </joint>
</robot>
