<?xml version="1.0" ?>
<!-- =================================================================================== -->
<!-- |    This document was autogenerated by xacro from panda_arm_hand_on_carter.urdf.xacro | -->
<!-- |    EDITING THIS FILE BY HAND IS NOT RECOMMENDED                                 | -->
<!-- =================================================================================== -->
<robot name="franka_carter" xmlns:xacro="http://www.ros.org/wiki/xacro">
  <link name="world_link"/>
  <link name="base_link_0"/>
  <link name="base_link_1"/>
  <joint name="x" type="prismatic">
    <parent link="world_link"/>
    <child link="base_link_0"/>
    <axis xyz="1 0 0"/>
    <limit effort="1000.0" lower="-5" upper="5" velocity="1.0"/>
  </joint>
  <joint name="y" type="prismatic">
    <parent link="base_link_0"/>
    <child link="base_link_1"/>
    <axis xyz="0 1 0"/>
    <limit effort="1000.0" lower="-5" upper="5" velocity="1.0"/>
  </joint>
  <joint name="theta" type="continuous">
    <parent link="base_link_1"/>
    <child link="chassis_link"/>
    <axis xyz="0 0 1"/>
    <limit effort="1000.0" velocity="1.5708"/>
  </joint>

  <material name="black">
    <color rgba=".1 .1 .1 1"/>
  </material>
  <material name="gray">
    <color rgba=".5 .5 .5 1"/>
  </material>
  <material name="white">
    <color rgba="1 1 1 1"/>
  </material>
  <material name="yellow">
    <color rgba="1 1 0 1"/>
  </material>
  <link name="chassis_link">
    <visual>
      <origin rpy="0 0 0" xyz="0 0 0"/>
      <geometry>
        <mesh filename="package://carter/meshes/chassis_franka.obj"/>
      </geometry>
      <material name="gray"/>
    </visual>
    <collision>
      <origin rpy="0 0 0" xyz="0 0 0"/>
      <geometry>
        <mesh filename="package://carter/meshes/chassis_franka.obj"/>
      </geometry>
    </collision>
    <inertial>
      <origin rpy="0 0 0" xyz="0.000000 0.000000 0.000000"/>
      <mass value="45.88"/>
      <inertia ixx="1.182744" ixy="0.017957" ixz="-0.077476" iyx="0.017957" iyy="0.538664" iyz="0.000018" izx="-0.077476" izy="0.000018" izz="1.240229"/>
    </inertial>
  </link>
  <link name="left_wheel_link">
    <visual>
      <origin rpy="1.57057 -1.57057 0" xyz="0 0 0"/>
      <geometry>
        <mesh filename="package://carter/meshes/side_wheel.obj"/>
      </geometry>
      <material name="black"/>
    </visual>
    <collision>
      <origin rpy="1.57057 -1.57057 0" xyz="0 0 0"/>
      <geometry>
        <mesh filename="package://carter/meshes/side_wheel.obj"/>
      </geometry>
    </collision>
    <inertial>
      <origin rpy="0 0 0" xyz="0.000000 0.000000 0.000000"/>
      <mass value="4.195729"/>
      <inertia ixx="0.063680" ixy="0.000000" ixz="0.000000" iyx="0.000000" iyy="0.121410" iyz="0.000000" izx="0.000000" izy="0.000000" izz="0.063680"/>
    </inertial>
  </link>
  <link name="right_wheel_link">
    <visual>
      <origin rpy="-1.57057 -1.57057 0" xyz="0 0 0"/>
      <geometry>
        <mesh filename="package://carter/meshes/side_wheel.obj"/>
      </geometry>
      <material name="black"/>
    </visual>
    <collision>
      <origin rpy="-1.57057 -1.57057 0" xyz="0 0 0"/>
      <geometry>
        <mesh filename="package://carter/meshes/side_wheel.obj"/>
      </geometry>
    </collision>
    <inertial>
      <origin rpy="0 0 0" xyz="0.000000 0.000000 0.000000"/>
      <mass value="4.195729"/>
      <inertia ixx="0.063680" ixy="0.000000" ixz="0.000000" iyx="0.000000" iyy="0.121410" iyz="0.000000" izx="0.000000" izy="0.000000" izz="0.063680"/>
    </inertial>
  </link>
  <link name="rear_pivot_link">
    <visual>
      <origin rpy="-1.57057 0 0" xyz="-.03809695 0 -.088"/>
      <geometry>
        <mesh filename="package://carter/meshes/pivot.obj"/>
      </geometry>
      <material name="black"/>
    </visual>
    <collision>
      <origin rpy="-1.57057 0 0" xyz="-.03809695 0 -.088"/>
      <geometry>
        <mesh filename="package://carter/meshes/pivot.obj"/>
      </geometry>
    </collision>
    <inertial>
      <origin rpy="0 0 0" xyz="0.000000 0.000000 0.000000"/>
      <mass value="0.579519"/>
      <inertia ixx="0.001361" ixy="-0.000003" ixz="0.000347" iyx="-0.000003" iyy="0.001287" iyz="-0.000010" izx="0.000347" izy="-0.000010" izz="0.000632"/>
    </inertial>
  </link>
  <link name="rear_wheel_link">
    <visual>
      <origin rpy="1.57057 0 0" xyz="0 0 0"/>
      <geometry>
        <mesh filename="package://carter/meshes/caster_wheel.obj"/>
      </geometry>
      <material name="gray"/>
    </visual>
    <collision>
      <origin rpy="1.57057 0 0" xyz="0 0 0"/>
      <geometry>
        <mesh filename="package://carter/meshes/caster_wheel.obj"/>
      </geometry>
    </collision>
    <inertial>
      <origin rpy="0 0 0" xyz="0.000000 0.000000 0.000000"/>
      <mass value="1.25"/>
      <inertia ixx="0.001442" ixy="0.000000" ixz="0.000000" iyx="0.000000" iyy="0.002493" iyz="0.000000" izx="0.000000" izy="0.000000" izz="0.001442"/>
    </inertial>
  </link>
  <link name="front_pivot_link">
    <visual>
      <origin rpy="-1.57057 0 0" xyz="-.03809695 0 -.088"/>
      <geometry>
        <mesh filename="package://carter/meshes/pivot.obj"/>
      </geometry>
      <material name="black"/>
    </visual>
    <collision>
      <origin rpy="-1.57057 0 0" xyz="-.03809695 0 -.088"/>
      <geometry>
        <mesh filename="package://carter/meshes/pivot.obj"/>
      </geometry>
    </collision>
    <inertial>
      <origin rpy="0 0 0" xyz="0.000000 0.000000 0.000000"/>
      <mass value="0.579519"/>
      <inertia ixx="0.001361" ixy="-0.000003" ixz="0.000347" iyx="-0.000003" iyy="0.001287" iyz="-0.000010" izx="0.000347" izy="-0.000010" izz="0.000632"/>
    </inertial>
  </link>
  <link name="front_wheel_link">
    <visual>
      <origin rpy="1.57057 0 0" xyz="0 0 0"/>
      <geometry>
        <mesh filename="package://carter/meshes/caster_wheel.obj"/>
      </geometry>
      <material name="gray"/>
    </visual>
    <collision>
      <origin rpy="1.57057 0 0" xyz="0 0 0"/>
      <geometry>
        <mesh filename="package://carter/meshes/caster_wheel.obj"/>
      </geometry>
    </collision>
    <inertial>
      <origin rpy="0 0 0" xyz="0.000000 0.000000 0.000000"/>
      <mass value="1.25"/>
      <inertia ixx="0.001442" ixy="0.000000" ixz="0.000000" iyx="0.000000" iyy="0.002493" iyz="0.000000" izx="0.000000" izy="0.000000" izz="0.001442"/>
    </inertial>
  </link>
  <link name="com_offset">
    <visual>
      <origin rpy="0 0 0" xyz="-.23 0 .02"/>
      <geometry>
        <box size=".25 .25 .1"/>
      </geometry>
      <material name="gray"/>
    </visual>
    <collision>
      <origin rpy="0 0 0" xyz="-.23 0 .02"/>
      <geometry>
        <box size=".25 .25 .1"/>
      </geometry>
    </collision>
    <inertial>
      <origin rpy="0 0 0" xyz="0.000000 0.000000 0.000000"/>
      <mass value="20.0"/>
      <inertia ixx="1.208" ixy="0" ixz="0" iyy="1.208" iyz="0" izz="2.08"/>
    </inertial>
  </link>
  <joint name="com_link" type="fixed">
    <origin rpy="0 0 0" xyz="0 0 0"/>
    <axis xyz="0 1 0"/>
    <parent link="chassis_link"/>
    <child link="com_offset"/>
  </joint>
  <link name="batteries_link">
    <visual>
      <origin rpy="0 0 0" xyz="0 0 0"/>
      <geometry>
        <box size=".1 .3 .2"/>
      </geometry>
      <material name="gray"/>
    </visual>
    <collision>
      <origin rpy="0 0 0" xyz="0 0 0"/>
      <geometry>
        <box size=".1 .3 .2"/>
      </geometry>
    </collision>
    <inertial>
      <origin rpy="0 0 0" xyz="0.000000 0.000000 0.000000"/>
      <mass value="20"/>
      <inertia ixx="0.216" ixy="0" ixz="0" iyx="0" iyy=".083" iyz="0" izx="0" izy="0" izz=".167"/>
    </inertial>
  </link>
  <joint name="batteries_joint" type="fixed">
    <origin xyz="0.31 0 0.09"/>
    <parent link="chassis_link"/>
    <child link="batteries_link"/>
  </joint>
  <joint name="left_wheel" type="continuous">
    <origin rpy="0 0 0" xyz="0 0.31420517 0"/>
    <axis xyz="0 1 0"/>
    <parent link="chassis_link"/>
    <child link="left_wheel_link"/>
  </joint>
  <joint name="right_wheel" type="continuous">
    <origin rpy="0 0 0" xyz="0 -0.31420517 0"/>
    <axis xyz="0 1 0"/>
    <parent link="chassis_link"/>
    <child link="right_wheel_link"/>
  </joint>
  <joint name="rear_pivot" type="continuous">
    <origin rpy="0 0 0" xyz="-0.31613607 0 -.0758"/>
    <axis xyz="0 0 1"/>
    <parent link="chassis_link"/>
    <child link="rear_pivot_link"/>
  </joint>
  <joint name="rear_axle" type="continuous">
    <origin rpy="0 0 0" xyz="-.03809695 0 -.088"/>
    <axis xyz="0 1 0"/>
    <parent link="rear_pivot_link"/>
    <child link="rear_wheel_link"/>
  </joint>
  <joint name="front_pivot" type="continuous">
    <origin rpy="0 0 0" xyz="0.31613607 0 -.0758"/>
    <axis xyz="0 0 1"/>
    <parent link="chassis_link"/>
    <child link="front_pivot_link"/>
  </joint>
  <joint name="front_axle" type="continuous">
    <origin rpy="0 0 0" xyz="-.03809695 0 -.088"/>
    <axis xyz="0 1 0"/>
    <parent link="front_pivot_link"/>
    <child link="front_wheel_link"/>
  </joint>
  <joint name="panda_joint_chassis_link" type="fixed">
    <parent link="chassis_link"/>
    <child link="panda_link0"/>
    <origin rpy="0 0 0" xyz="-.035 0 0.525"/>
  </joint>
  <link name="panda_link0">
    <visual>
      <geometry>
        <mesh filename="package://franka_description/meshes/visual/link0.dae"/>
      </geometry>
      <!--material name="white"/-->
    </visual>
    <collision>
      <geometry>
        <mesh filename="package://franka_description/meshes/collision/link0.stl"/>
      </geometry>
    </collision>
    <inertial>
      <origin rpy="0 0 0" xyz="0 0 0"/>
      <mass value="2.8142028896"/>
      <inertia ixx="0.0129886979" ixy="0.0" ixz="0.0" iyy="0.0165355284" iyz="0" izz="0.0203311636"/>
    </inertial>
  </link>
  <link name="panda_link1">
    <visual>
      <geometry>
        <mesh filename="package://franka_description/meshes/visual/link1.dae"/>
      </geometry>
      <!--material name="white"/-->
    </visual>
    <collision>
      <geometry>
        <mesh filename="package://franka_description/meshes/collision/link1.stl"/>
      </geometry>
    </collision>
    <inertial>
      <origin rpy="0 0 0" xyz="0 0 0"/>
      <mass value="2.3599995791"/>
      <inertia ixx="0.0186863903" ixy="0.0" ixz="0.0" iyy="0.0143789874" iyz="0" izz="0.00906812"/>
    </inertial>
  </link>
  <joint name="panda_joint1" type="revolute">
    <safety_controller k_position="100.0" k_velocity="40.0" soft_lower_limit="-2.8973" soft_upper_limit="2.8973"/>
    <origin rpy="0 0 0" xyz="0 0 0.333"/>
    <parent link="panda_link0"/>
    <child link="panda_link1"/>
    <axis xyz="0 0 1"/>
    <limit effort="87" lower="-2.8973" upper="2.8973" velocity="2.1750"/>
  </joint>
  <link name="panda_link2">
    <visual>
      <geometry>
        <mesh filename="package://franka_description/meshes/visual/link2.dae"/>
      </geometry>
      <!--material name="white"/-->
    </visual>
    <collision>
      <geometry>
        <mesh filename="package://franka_description/meshes/collision/link2.stl"/>
      </geometry>
    </collision>
    <inertial>
      <origin rpy="0 0 0" xyz="0 0 0"/>
      <mass value="2.379518833"/>
      <inertia ixx="0.0190388734" ixy="0.0" ixz="0.0" iyy="0.0091429124" iyz="0" izz="0.014697537"/>
    </inertial>
  </link>
  <joint name="panda_joint2" type="revolute">
    <safety_controller k_position="100.0" k_velocity="40.0" soft_lower_limit="-1.7628" soft_upper_limit="1.7628"/>
    <origin rpy="-1.57079632679 0 0" xyz="0 0 0"/>
    <parent link="panda_link1"/>
    <child link="panda_link2"/>
    <axis xyz="0 0 1"/>
    <limit effort="87" lower="-1.7628" upper="1.7628" velocity="2.1750"/>
  </joint>
  <link name="panda_link3">
    <visual>
      <geometry>
        <mesh filename="package://franka_description/meshes/visual/link3.dae"/>
      </geometry>
      <!--material name="gray"/-->
    </visual>
    <collision>
      <geometry>
        <mesh filename="package://franka_description/meshes/collision/link3.stl"/>
      </geometry>
    </collision>
    <inertial>
      <origin rpy="0 0 0" xyz="0 0 0"/>
      <mass value="2.6498823337"/>
      <inertia ixx="0.0129300178" ixy="0.0" ixz="0.0" iyy="0.0150242121" iyz="0" izz="0.0142734598"/>
    </inertial>
  </link>
  <joint name="panda_joint3" type="revolute">
    <safety_controller k_position="100.0" k_velocity="40.0" soft_lower_limit="-2.8973" soft_upper_limit="2.8973"/>
    <origin rpy="1.57079632679 0 0" xyz="0 -0.316 0"/>
    <parent link="panda_link2"/>
    <child link="panda_link3"/>
    <axis xyz="0 0 1"/>
    <limit effort="87" lower="-2.8973" upper="2.8973" velocity="2.1750"/>
  </joint>
  <link name="panda_link4">
    <visual>
      <geometry>
        <mesh filename="package://franka_description/meshes/visual/link4.dae"/>
      </geometry>
      <!--material name="white"/-->
    </visual>
    <collision>
      <geometry>
        <mesh filename="package://franka_description/meshes/collision/link4.stl"/>
      </geometry>
    </collision>
    <inertial>
      <origin rpy="0 0 0" xyz="0 0 0"/>
      <mass value="2.6948018744"/>
      <inertia ixx="0.0133874611" ixy="0.0" ixz="0.0" iyy="0.014514325" iyz="0" izz="0.0155175551"/>
    </inertial>
  </link>
  <joint name="panda_joint4" type="revolute">
    <safety_controller k_position="100.0" k_velocity="40.0" soft_lower_limit="-3.0718" soft_upper_limit="-0.0698"/>
    <origin rpy="1.57079632679 0 0" xyz="0.0825 0 0"/>
    <parent link="panda_link3"/>
    <child link="panda_link4"/>
    <axis xyz="0 0 1"/>
    <limit effort="87" lower="-3.0718" upper="-0.0698" velocity="2.1750"/>
  </joint>
  <link name="panda_link5">
    <visual>
      <geometry>
        <mesh filename="package://franka_description/meshes/visual/link5.dae"/>
      </geometry>
      <!--material name="gray"/-->
    </visual>
    <collision>
      <geometry>
        <mesh filename="package://franka_description/meshes/collision/link5.stl"/>
      </geometry>
    </collision>
    <inertial>
      <origin rpy="0 0 0" xyz="0 0 0"/>
      <mass value="2.9812816864"/>
      <inertia ixx="0.0325565705" ixy="0.0" ixz="0.0" iyy="0.0270660472" iyz="0" izz="0.0115023375"/>
    </inertial>
  </link>
  <joint name="panda_joint5" type="revolute">
    <safety_controller k_position="100.0" k_velocity="40.0" soft_lower_limit="-2.8973" soft_upper_limit="2.8973"/>
    <origin rpy="-1.57079632679 0 0" xyz="-0.0825 0.384 0"/>
    <parent link="panda_link4"/>
    <child link="panda_link5"/>
    <axis xyz="0 0 1"/>
    <limit effort="12" lower="-2.8973" upper="2.8973" velocity="2.6100"/>
  </joint>
  <link name="panda_link6">
    <visual>
      <geometry>
        <mesh filename="package://franka_description/meshes/visual/link6.dae"/>
      </geometry>
      <!--material name="white"/-->
    </visual>
    <collision>
      <geometry>
        <mesh filename="package://franka_description/meshes/collision/link6.stl"/>
      </geometry>
    </collision>
    <inertial>
      <origin rpy="0 0 0" xyz="0 0 0"/>
      <mass value="1.1285806309"/>
      <inertia ixx="0.0026052565" ixy="0.0" ixz="0.0" iyy="0.0039897229" iyz="0" izz="0.0047048591"/>
    </inertial>
  </link>
  <joint name="panda_joint6" type="revolute">
    <safety_controller k_position="100.0" k_velocity="40.0" soft_lower_limit="-0.0175" soft_upper_limit="3.7525"/>
    <origin rpy="1.57079632679 0 0" xyz="0 0 0"/>
    <parent link="panda_link5"/>
    <child link="panda_link6"/>
    <axis xyz="0 0 1"/>
    <limit effort="12" lower="-0.0175" upper="3.7525" velocity="2.6100"/>
  </joint>
  <link name="panda_link7">
    <visual>
      <geometry>
        <mesh filename="package://franka_description/meshes/visual/link7.dae"/>
      </geometry>
      <!--material name="white"/-->
    </visual>
    <collision>
      <geometry>
        <mesh filename="package://franka_description/meshes/collision/link7.stl"/>
      </geometry>
    </collision>
    <inertial>
      <origin rpy="0 0 0" xyz="0 0 0"/>
      <mass value="0.4052912465"/>
      <inertia ixx="0.0006316592" ixy="0.0" ixz="0.0" iyy="0.0006319639" iyz="0" izz="0.0010607721"/>
    </inertial>
  </link>
  <joint name="panda_joint7" type="revolute">
    <safety_controller k_position="100.0" k_velocity="40.0" soft_lower_limit="-2.8973" soft_upper_limit="2.8973"/>
    <origin rpy="1.57079632679 0 0" xyz="0.088 0 0"/>
    <parent link="panda_link6"/>
    <child link="panda_link7"/>
    <axis xyz="0 0 1"/>
    <limit effort="12" lower="-2.8973" upper="2.8973" velocity="2.6100"/>
  </joint>
  <link name="panda_link8"/>
  <joint name="panda_joint8" type="fixed">
    <origin rpy="0 0 0" xyz="0 0 0.107"/>
    <parent link="panda_link7"/>
    <child link="panda_link8"/>
    <axis xyz="0 0 0"/>
  </joint>
  <joint name="panda_hand_joint" type="fixed">
    <parent link="panda_link8"/>
    <child link="panda_hand"/>
    <origin rpy="0 0 -0.785398163397" xyz="0 0 0"/>
  </joint>
  <link name="panda_hand">
    <visual>
      <geometry>
        <mesh filename="package://franka_description/meshes/visual/hand.dae"/>
      </geometry>
      <!--material name="white"/-->
    </visual>
    <collision>
      <geometry>
        <mesh filename="package://franka_description/meshes/collision/hand.stl"/>
      </geometry>
    </collision>
    <inertial>
      <origin rpy="0 0 0" xyz="0 0 0"/>
      <mass value="0.5583304799"/>
      <inertia ixx="0.0023394448" ixy="0.0" ixz="0.0" iyy="0.0005782786" iyz="0" izz="0.0021310296"/>
    </inertial>
  </link>
  <link name="panda_leftfinger">
    <visual>
      <geometry>
        <mesh filename="package://franka_description/meshes/visual/finger.dae"/>
      </geometry>
      <!--material name="white"/-->
    </visual>
    <collision>
      <geometry>
        <mesh filename="package://franka_description/meshes/collision/finger.stl"/>
      </geometry>
    </collision>
    <inertial>
      <origin rpy="0 0 0" xyz="0 0 0"/>
      <mass value="0.0140552232"/>
      <inertia ixx="4.20413082650939E-06" ixy="0.0" ixz="0.0" iyy="3.90263687466755E-06" iyz="0" izz="1.33474964199095E-06"/>
    </inertial>
  </link>
  <link name="panda_rightfinger">
    <visual>
      <origin rpy="0 0 3.14159265359" xyz="0 0 0"/>
      <geometry>
        <mesh filename="package://franka_description/meshes/visual/finger.dae"/>
      </geometry>
      <!--material name="white"/-->
    </visual>
    <collision>
      <origin rpy="0 0 3.14159265359" xyz="0 0 0"/>
      <geometry>
        <mesh filename="package://franka_description/meshes/collision/finger.stl"/>
      </geometry>
    </collision>
    <inertial>
      <origin rpy="0 0 0" xyz="0 0 0"/>
      <mass value="0.0140552232"/>
      <inertia ixx="4.20413082650939E-06" ixy="0.0" ixz="0.0" iyy="3.90263687466755E-06" iyz="0" izz="1.33474964199095E-06"/>
    </inertial>
  </link>
  <joint name="panda_finger_joint1" type="prismatic">
    <parent link="panda_hand"/>
    <child link="panda_leftfinger"/>
    <origin rpy="0 0 0" xyz="0 0 0.0584"/>
    <axis xyz="0 1 0"/>
    <limit effort="20" lower="0.0" upper="0.04" velocity="0.2"/>
  </joint>
  <joint name="panda_finger_joint2" type="prismatic">
    <parent link="panda_hand"/>
    <child link="panda_rightfinger"/>
    <origin rpy="0 0 0" xyz="0 0 0.0584"/>
    <axis xyz="0 -1 0"/>
    <limit effort="20" lower="0.0" upper="0.04" velocity="0.2"/>
    <mimic joint="panda_finger_joint1"/>
  </joint>
  <link name="right_gripper"/>
  <joint name="right_gripper" type="fixed">
    <origin rpy="0 0 2.35619449019" xyz="0.0 0 0.1"/>
    <axis xyz="0 0 1"/>
    <parent link="panda_link8"/>
    <child link="right_gripper"/>
  </joint>
</robot>
