<?xml version="1.0" ?>
<!-- =================================================================================== -->
<!-- |    This document was autogenerated by xacro from movo.urdf.xacro                | -->
<!-- |    EDITING THIS FILE BY HAND IS NOT RECOMMENDED                                 | -->
<!-- =================================================================================== -->
<!--
Software License Agreement (BSD)
\file      movo.urdf.xacro
\authors   Patrick Hussey
\copyright Copyright (c) 2017, Kinova Robotics inc. All rights reserved.
Redistribution and use in source and binary forms, with or without modification,
are permitted provided that the following conditions are met:
    * Redistributions of source code must retain the above copyright notice,
      this list of conditions and the following disclaimer.
    * Redistributions in binary form must reproduce the above copyright notice,
      this list of conditions and the following disclaimer in the documentation
      and/or other materials provided with the distribution.
    * Neither the name of the copyright holder nor the names of its contributors
      may be used to endorse or promote products derived from this software
      without specific prior written permission.
THIS SOFTWARE IS PROVIDED BY THE COPYRIGHT HOLDERS AND CONTRIBUTORS
"AS IS" AND ANY EXPRESS OR IMPLIED WARRANTIES, INCLUDING, BUT NOT
LIMITED TO, THE IMPLIED WARRANTIES OF MERCHANTABILITY AND FITNESS FOR
A PARTICULAR PURPOSE ARE DISCLAIMED. IN NO EVENT SHALL THE COPYRIGHT HOLDER OR
CONTRIBUTORS BE LIABLE FOR ANY DIRECT, INDIRECT, INCIDENTAL, SPECIAL,
EXEMPLARY, OR CONSEQUENTIAL DAMAGES (INCLUDING, BUT NOT LIMITED TO,
PROCUREMENT OF SUBSTITUTE GOODS OR SERVICES; LOSS OF USE, DATA, OR
PROFITS; OR BUSINESS INTERRUPTION) HOWEVER CAUSED AND ON ANY THEORY OF
LIABILITY, WHETHER IN CONTRACT, STRICT LIABILITY, OR TORT (INCLUDING
NEGLIGENCE OR OTHERWISE) ARISING IN ANY WAY OUT OF THE USE OF THIS
SOFTWARE, EVEN IF ADVISED OF THE POSSIBILITY OF SUCH DAMAGE.
-->
<!-- https://github.mit.edu/Learning-and-Intelligent-Systems/ltamp_pr2/blob/master/control_tools/ik/ik_tools/movo_ik/movo_robotiq.urdf -->
<robot name="movo" xmlns:xacro="http://ros.org/wiki/xacro">

  <!-- Modification -->
  <link name="world_link">
    <inertial>
      <mass value="1"/>
      <inertia ixx="0.04" ixy="0.00" ixz="0.00" iyy="0.04" iyz="0.00" izz="0.02"/>
    </inertial>
  </link>
  <link name="base_link_0">
    <inertial>
      <mass value="1"/>
      <inertia ixx="0.04" ixy="0.00" ixz="0.00" iyy="0.04" iyz="0.00" izz="0.02"/>
    </inertial>
  </link>
  <link name="base_link_1">
    <inertial>
      <mass value="1"/>
      <inertia ixx="0.04" ixy="0.00" ixz="0.00" iyy="0.04" iyz="0.00" izz="0.02"/>
    </inertial>
  </link>
  <joint name="x" type="prismatic">
    <parent link="world_link"/>
    <child link="base_link_0"/>
    <axis xyz="1 0 0"/>
    <limit effort="1000.0" lower="-2.5" upper="2.5" velocity="1.0"/>
  </joint>
  <joint name="y" type="prismatic">
    <parent link="base_link_0"/>
    <child link="base_link_1"/>
    <axis xyz="0 1 0"/>
    <limit effort="1000.0" lower="-2.5" upper="2.5" velocity="1.0"/>
  </joint>
  <joint name="theta" type="continuous">
    <parent link="base_link_1"/>
    <child link="base_link"/>
    <axis xyz="0 0 1"/>
    <limit effort="1000.0" velocity="1.5708"/>
  </joint>
  <!-- Base link is the center of the robot's chassis between the motors projected on the ground -->
  <link name="base_link">
    <inertial>
      <mass value="1"/>
      <inertia ixx="0.04" ixy="0.00" ixz="0.00" iyy="0.04" iyz="0.00" izz="0.02"/>
    </inertial>
  </link>
  <joint name="base_chassis_joint" type="fixed">
    <origin rpy="0 0 0" xyz="0 0 0.0762"/>
    <parent link="base_link"/>
    <child link="base_chassis_link"/>
  </joint>
  <link name="base_chassis_link">
    <inertial>
      <mass value="1"/>
      <inertia ixx="0.04" ixy="0.00" ixz="0.00" iyy="0.04" iyz="0.00" izz="0.02"/>
    </inertial>
    <collision name="base_chassis_link">
      <origin rpy="0 0 0" xyz="0 0 0"/>
      <geometry>
        <mesh filename="package://movo_description_drake/meshes/movo_components/collision/vector_base_collision.obj"/>
      </geometry>
    </collision>
    <visual>
      <origin rpy="0 0 0" xyz="0 0 0"/>
      <geometry>
        <mesh filename="package://movo_description_drake/meshes/movo_components/collision/vector_base_collision.obj"/>
      </geometry>
    </visual>
  </link>
  <joint name="linear_actuator_fixed_joint" type="fixed">
    <origin rpy="0 0 0" xyz="0 0 0"/>
    <parent link="base_chassis_link"/>
    <child link="linear_actuator_fixed_link"/>
  </joint>
  <link name="linear_actuator_fixed_link">
    <inertial>
      <mass value="1"/>
      <inertia ixx="0.04" ixy="0.00" ixz="0.00" iyy="0.04" iyz="0.00" izz="0.02"/>
    </inertial>
    <collision name="linear_actuator_fixed_link">
      <origin rpy="0 0 0" xyz="0 0 0"/>
      <geometry>
        <mesh filename="package://movo_description_drake/meshes/movo_components/collision/movo_fixed_body_collision.obj"/>
      </geometry>
    </collision>
    <visual>
      <origin rpy="0 0 0" xyz="0 0 0"/>
      <geometry>
        <mesh filename="package://movo_description_drake/meshes/movo_components/collision/movo_fixed_body_collision.obj"/>
      </geometry>
    </visual>
  </link>
  <joint name="linear_joint" type="prismatic">
    <parent link="linear_actuator_fixed_link"/>
    <child link="linear_actuator_link"/>
    <origin rpy="0 0 0" xyz="0.0771402 0 0.3938763"/>
    <axis xyz="0 0 1"/>
    <limit effort="1000" lower="0.0" upper="0.472" velocity="0.20"/>
    <dynamics damping="0.0" friction="0.0"/>
  </joint>
  <link name="linear_actuator_link">
    <visual>
      <origin rpy="0 0 0" xyz="0 0 0"/>
      <geometry>
        <mesh filename="package://movo_description_drake/meshes/movo_components/collision/movo_upper_body_collision.obj"/>
      </geometry>
    </visual>
    <collision name="linear_actuator_link">
      <origin rpy="0 0 0" xyz="0 0 0"/>
      <geometry>
        <mesh filename="package://movo_description_drake/meshes/movo_components/collision/movo_upper_body_collision_modified.obj"/>
      </geometry>
    </collision>
    <inertial>
      <mass value="1"/>
      <inertia ixx="0.04" ixy="0.00" ixz="0.00" iyy="0.04" iyz="0.00" izz="0.02"/>
    </inertial>
  </link>

  <transmission name="linear_trans">
    <type>transmission_interface/SimpleTransmission</type>
    <joint name="linear_joint">
      <hardwareInterface>PositionJointInterface</hardwareInterface>
    </joint>
    <actuator name="linear_motor">
      <mechanicalReduction>1</mechanicalReduction>
    </actuator>
  </transmission>
  <link name="sic_imu_frame">
    <inertial>
      <mass value="1"/>
      <inertia ixx="0.04" ixy="0.00" ixz="0.00" iyy="0.04" iyz="0.00" izz="0.02"/>
    </inertial>
  </link>
  <joint name="sic_imu_joint" type="fixed">
    <origin rpy="3.14159 0 1.570795" xyz="0.0326421 0.0899448 0.0082008"/>
    <parent link="base_chassis_link"/>
    <child link="sic_imu_frame"/>
  </joint>

  <joint name="front_laser_joint" type="fixed">
    <origin rpy="3.14159 0 0" xyz="0.3375 0 0.1439106"/>
    <parent link="base_chassis_link"/>
    <child link="front_laser_link"/>
  </joint>
  <link name="front_laser_link">
    <visual>
      <origin rpy="0 0 0" xyz="0 0 0"/>
      <geometry>
        <box size="0.1 0.1 0.1"/>
      </geometry>
    </visual>
    <collision name="front_laser_link">
      <origin rpy="0 0 0" xyz="0 0 0"/>
      <geometry>
        <box size="0.1 0.1 0.1"/>
      </geometry>
    </collision>
    <inertial>
      <mass value="1"/>
      <inertia ixx="0.04" ixy="0.00" ixz="0.00" iyy="0.04" iyz="0.00" izz="0.02"/>
    </inertial>
  </link>

  <joint name="rear_laser_joint" type="fixed">
    <origin rpy="3.14159 0 3.14159" xyz="-0.3375 0 0.1439106"/>
    <parent link="base_chassis_link"/>
    <child link="rear_laser_link"/>
  </joint>
  <link name="rear_laser_link">
    <visual>
      <origin rpy="0 0 0" xyz="0 0 0"/>
      <geometry>
        <box size="0.1 0.1 0.1"/>
      </geometry>
    </visual>
    <collision name="rear_laser_link">
      <origin rpy="0 0 0" xyz="0 0 0"/>
      <geometry>
        <box size="0.1 0.1 0.1"/>
      </geometry>
    </collision>
    <inertial>
      <mass value="1"/>
      <inertia ixx="0.04" ixy="0.00" ixz="0.00" iyy="0.04" iyz="0.00" izz="0.02"/>
    </inertial>
  </link>

  <joint name="pan_base_joint" type="fixed">
    <origin rpy="0 0 0" xyz="0.19735 0 0.3449888"/>
    <parent link="linear_actuator_link"/>
    <child link="pan_base_link"/>
  </joint>
  <link name="pan_base_link">
    <visual>
      <origin rpy="0 0 0" xyz="0 0 0"/>
      <geometry>
        <mesh filename="package://movo_description_drake/meshes/pan_tilt/collision/pan_tilt_base.obj"/>
      </geometry>
    </visual>
    <collision name="pan_base_link">
      <origin rpy="0 0 0" xyz="0 0 0"/>

      <geometry>
        <mesh filename="package://movo_description_drake/meshes/pan_tilt/collision/pan_tilt_base.obj"/>
      </geometry>
    </collision>
    <inertial>
      <mass value="1"/>
      <inertia ixx="0.04" ixy="0.00" ixz="0.00" iyy="0.04" iyz="0.00" izz="0.02"/>
    </inertial>
  </link>
  <joint name="pan_joint" type="revolute">
    <origin rpy="3.14159 0 0" xyz="0 0 0.05525"/>
    <axis xyz="0 0 1"/>
    <parent link="pan_base_link"/>
    <child link="pan_link"/>
    <limit effort="7.0" lower="-1.570796326794897" upper="1.570796326794897" velocity="0.907571211"/>
  </joint>
  <transmission name="pan_trans" type="SimpleTransmission">
    <type>transmission_interface/SimpleTransmission</type>
    <joint name="pan_joint">
      <hardwareInterface>PositionJointInterface</hardwareInterface>
    </joint>
    <actuator name="pan_actuator">
      <mechanicalReduction>1</mechanicalReduction>
    </actuator>
  </transmission>
  <link name="pan_link">
    <visual>
      <origin rpy="0 0 0" xyz="0 0 0"/>
      <geometry>
        <mesh filename="package://movo_description_drake/meshes/pan_tilt/collision/pan_link.obj"/>
      </geometry>
    </visual>
    <collision name="pan_link">
      <origin rpy="0 0 0" xyz="0 0 0"/>
      <geometry>
        <mesh filename="package://movo_description_drake/meshes/pan_tilt/collision/pan_link.obj"/>
      </geometry>
    </collision>
    <inertial>
      <mass value="1"/>
      <inertia ixx="0.04" ixy="0.00" ixz="0.00" iyy="0.04" iyz="0.00" izz="0.02"/>
    </inertial>
  </link>
  <joint name="tilt_joint" type="revolute">
    <origin rpy="-1.570795 1.570795 0" xyz="0 0.026 -0.09075"/>
    <axis xyz="0 0 1"/>
    <parent link="pan_link"/>
    <child link="tilt_link"/>
    <limit effort="7.0" lower="-1.570796326794897" upper="1.570796326794897" velocity="0.907571211"/>
  </joint>
  <transmission name="tilt_trans" type="SimpleTransmission">
    <type>transmission_interface/SimpleTransmission</type>
    <joint name="tilt_joint">
      <hardwareInterface>PositionJointInterface</hardwareInterface>
    </joint>
    <actuator name="tilt_actuator">
      <mechanicalReduction>1</mechanicalReduction>
    </actuator>
  </transmission>
  <link name="tilt_link">
    <visual>
      <origin rpy="0 0 0" xyz="0 0 0"/>
      <geometry>
        <mesh filename="package://movo_description_drake/meshes/pan_tilt/collision/tilt_link.obj"/>
      </geometry>
    </visual>
    <collision name="tilt_link">
      <origin rpy="0 0 0" xyz="0 0 0"/>
      <geometry>
        <mesh filename="package://movo_description_drake/meshes/pan_tilt/collision/tilt_link.obj"/>
      </geometry>
    </collision>
    <inertial>
      <mass value="1"/>
      <inertia ixx="0.04" ixy="0.00" ixz="0.00" iyy="0.04" iyz="0.00" izz="0.02"/>
    </inertial>
  </link>
  <joint name="kinect2_joint" type="fixed">
    <origin rpy="-1.570795 0 -1.570795" xyz="0.05825 -0.0105875 -0.026"/>
    <parent link="tilt_link"/>
    <child link="kinect2_link"/>
  </joint>
  <link name="kinect2_link">
    <inertial>
      <mass value="1"/>
      <inertia ixx="0.04" ixy="0.00" ixz="0.00" iyy="0.04" iyz="0.00" izz="0.02"/>
    </inertial>
    <visual>
      <origin rpy="0 0 0" xyz="0 0 0"/>
      <geometry>
        <mesh filename="package://movo_description_drake/meshes/sensors/collision/kinect_one_collision.obj"/>
      </geometry>
    </visual>
    <collision name="kinect2_link">
      <origin rpy="0 0 0" xyz="0 0 0"/>

      <geometry>
        <mesh filename="package://movo_description_drake/meshes/sensors/collision/kinect_one_collision.obj"/>
      </geometry>
    </collision>
  </link>
  <link name="kinect2_ir_link">
    <inertial>
      <mass value="1"/>
      <inertia ixx="0.04" ixy="0.00" ixz="0.00" iyy="0.04" iyz="0.00" izz="0.02"/>
    </inertial>
  </link>
  <joint name="kinect2_ir_joint" type="fixed">
    <parent link="kinect2_link"/>
    <child link="kinect2_ir_link"/>
    <origin rpy="0 0 0" xyz="0.0245 -0.03325  0.04201"/>
  </joint>
  <link name="kinect2_ir_optical_frame">
    <inertial>
      <mass value="1"/>
      <inertia ixx="0.04" ixy="0.00" ixz="0.00" iyy="0.04" iyz="0.00" izz="0.02"/>
    </inertial>
  </link>
  <joint name="kinect2_ir_optical_frame_joint" type="fixed">
    <origin rpy="-1.570795 0 -1.570795" xyz="0 0 0"/>
    <parent link="kinect2_ir_link"/>
    <child link="kinect2_ir_optical_frame"/>
  </joint>
  <link name="kinect2_rgb_link">
    <inertial>
      <mass value="1"/>
      <inertia ixx="0.04" ixy="0.00" ixz="0.00" iyy="0.04" iyz="0.00" izz="0.02"/>
    </inertial>
  </link>
  <joint name="kinect2_rgb_joint" type="fixed">
    <parent link="kinect2_ir_link"/>
    <child link="kinect2_rgb_link"/>
    <origin rpy="0 0 0" xyz="0 -0.06175  0"/>
  </joint>
  <link name="kinect2_rgb_optical_frame">
    <inertial>
      <mass value="1"/>
      <inertia ixx="0.04" ixy="0.00" ixz="0.00" iyy="0.04" iyz="0.00" izz="0.02"/>
    </inertial>
  </link>
  <joint name="kinect2_rgb_optical_joint" type="fixed">
    <parent link="kinect2_rgb_link"/>
    <child link="kinect2_rgb_optical_frame"/>
    <origin rpy="-1.570795 0 -1.570795" xyz="0 0 0"/>
  </joint>

  <joint name="lower_body_joint" type="fixed">
    <origin rpy="0 0 0" xyz="0 0 0"/>
    <parent link="base_chassis_link"/>
    <child link="lower_body_link"/>
  </joint>
  <link name="lower_body_link">
    <inertial>
      <mass value="1"/>
      <inertia ixx="0.04" ixy="0.00" ixz="0.00" iyy="0.04" iyz="0.00" izz="0.02"/>
    </inertial>
    <visual>
      <origin rpy="0 0 0" xyz="0 0 0"/>
      <geometry>
        <mesh filename="package://movo_description_drake/meshes/movo_body/movo_lower_body.obj"/>
      </geometry>
    </visual>
  </link>
  <joint name="upper_body_joint" type="fixed">
    <origin rpy="0 0 0" xyz="0 0 0"/>
    <parent link="linear_actuator_link"/>
    <child link="upper_body_link"/>
  </joint>
  <link name="upper_body_link">
    <inertial>
      <mass value="1"/>
      <inertia ixx="0.04" ixy="0.00" ixz="0.00" iyy="0.04" iyz="0.00" izz="0.02"/>
    </inertial>
    <visual>
      <origin rpy="0 0 0" xyz="0 0 0"/>
      <geometry>
        <mesh filename="package://movo_description_drake/meshes/movo_body/movo_upper_body.obj"/>
      </geometry>
    </visual>
  </link>
  <joint name="mid_body_joint" type="prismatic">
    <parent link="base_chassis_link"/>
    <child link="mid_body_link"/>
    <origin rpy="0 0 0" xyz="0.0771402 0 0.3938763"/>
    <axis xyz="0 0 1"/>
    <limit effort="1000" lower="0.0" upper="0.2545608" velocity="0.20"/>
    <dynamics damping="0.0" friction="0.0"/>
    <mimic joint="linear_joint" multiplier="0.5" offset="0.0"/>
  </joint>
  <link name="mid_body_link">
    <inertial>
      <mass value="1"/>
      <inertia ixx="0.04" ixy="0.00" ixz="0.00" iyy="0.04" iyz="0.00" izz="0.02"/>
    </inertial>
    <visual>
      <origin rpy="0 0 0" xyz="0 0 0"/>
      <geometry>
        <mesh filename="package://movo_description_drake/meshes/movo_body/movo_mid_body.obj"/>
      </geometry>
    </visual>
  </link>
  <joint name="right_kinova_joint" type="fixed">
    <parent link="linear_actuator_link"/>
    <child link="right_base_link"/>
    <origin rpy="-1.570796325 0 -1.570796325" xyz="0.0261046 -0.13335 0.2799937"/>
  </joint>
  <link name="right_base_link">
    <visual>
      <origin rpy="0 0 0" xyz="0 0 0"/>
      <geometry>
        <mesh filename="package://movo_description_drake/meshes/manipulation/jaco/collision/base.obj"/>
      </geometry>
    </visual>
    <collision name="right_base_link">
      <origin rpy="0 0 0" xyz="0 0 0"/>
      <geometry>
        <mesh filename="package://movo_description_drake/meshes/manipulation/jaco/collision/base.obj"/>
      </geometry>
    </collision>
    <inertial>
      <mass value="1"/>
      <inertia ixx="0.04" ixy="0.00" ixz="0.00" iyy="0.04" iyz="0.00" izz="0.02"/>
    </inertial>
  </link>
  <joint name="right_shoulder_pan_joint" type="revolute">
    <parent link="right_base_link"/>
    <child link="right_shoulder_link"/>
    <origin rpy="0 3.14159265 0" xyz="0 0 0.0625"/>
    <axis xyz="0 0 1"/>
    <limit effort="18000.0" lower="-3.14159265" upper="3.14159265" velocity="0.691150384"/>
    <dynamics damping="0.01" friction="0.0"/>
  </joint>
  <link name="right_shoulder_link">
    <visual>
      <origin rpy="0 0 0" xyz="0 0 0"/>
      <geometry>
        <mesh filename="package://movo_description_drake/meshes/manipulation/jaco/collision/shoulder_7dof.obj"/>
      </geometry>
    </visual>
    <collision name="right_shoulder_link">
      <origin rpy="0 0 0" xyz="0 0 0"/>
      <geometry>
        <mesh filename="package://movo_description_drake/meshes/manipulation/jaco/collision/shoulder_7dof.obj"/>
      </geometry>
    </collision>
    <inertial>
      <mass value="1"/>
      <inertia ixx="0.04" ixy="0.00" ixz="0.00" iyy="0.04" iyz="0.00" izz="0.02"/>
    </inertial>
  </link>

  <joint name="right_shoulder_lift_joint" type="revolute">
    <parent link="right_shoulder_link"/>
    <child link="right_arm_half_1_link"/>
    <origin rpy="1.570796325 0 0" xyz="0 0 -0.11875"/>
    <axis xyz="0 0 1"/>
    <limit effort="30000.5" lower="-2.238" upper="2.238" velocity="0.691150384"/>
    <dynamics damping="0.01" friction="0.0"/>
  </joint>
  <link name="right_arm_half_1_link">
    <visual>
        <origin rpy="0 0 0" xyz="0 0 0"/>
      <geometry>
        <mesh filename="package://movo_description_drake/meshes/manipulation/jaco/collision/arm_half_1.obj"/>
      </geometry>
    </visual>
    <collision name="right_arm_half_1_link">
      <origin rpy="0 0 0" xyz="0 0 0"/>
      <geometry>
        <mesh filename="package://movo_description_drake/meshes/manipulation/jaco/collision/arm_half_1.obj"/>
      </geometry>
    </collision>
    <inertial>
      <mass value="1"/>
      <inertia ixx="0.04" ixy="0.00" ixz="0.00" iyy="0.04" iyz="0.00" izz="0.02"/>
    </inertial>
  </link>
  <joint name="right_arm_half_joint" type="revolute">
    <parent link="right_arm_half_1_link"/>
    <child link="right_arm_half_2_link"/>
    <origin rpy="-1.570796325 0 0" xyz="0 -0.205 0"/>
    <axis xyz="0 0 1"/>
    <limit effort="30000.5" lower="-3.14159265" upper="3.14159265" velocity="0.691150384"/>
    <dynamics damping="0.01" friction="0.0"/>
  </joint>
  <link name="right_arm_half_2_link">
    <visual>
      <origin rpy="0 0 0" xyz="0 0 0"/>

      <geometry>
        <mesh filename="package://movo_description_drake/meshes/manipulation/jaco/collision/arm_half_2.obj"/>
      </geometry>
    </visual>
    <collision name="right_arm_half_2_link">
      <origin rpy="0 0 0" xyz="0 0 0"/>

      <geometry>
        <mesh filename="package://movo_description_drake/meshes/manipulation/jaco/collision/arm_half_2.obj"/>
      </geometry>
    </collision>
    <inertial>
      <mass value="1"/>
      <inertia ixx="0.04" ixy="0.00" ixz="0.00" iyy="0.04" iyz="0.00" izz="0.02"/>
    </inertial>
  </link>

  <joint name="right_elbow_joint" type="revolute">
    <parent link="right_arm_half_2_link"/>
    <child link="right_forearm_link"/>
    <origin rpy="-1.570796325 0 0" xyz="0 0 -0.205"/>
    <axis xyz="0 0 1"/>
    <limit effort="18000.0" lower="-2.809" upper="2.809" velocity="0.691150384"/>
    <dynamics damping="0.01" friction="0.0"/>
  </joint>
  <link name="right_forearm_link">
    <visual>
        <origin rpy="0 0 0" xyz="0 0 0"/>
      <geometry>
        <mesh filename="package://movo_description_drake/meshes/manipulation/jaco/collision/forearm_7dof.obj"/>
      </geometry>
    </visual>
    <collision name="right_forearm_link">
      <origin rpy="0 0 0" xyz="0 0 0"/>
      <geometry>
        <mesh filename="package://movo_description_drake/meshes/manipulation/jaco/collision/forearm_7dof.obj"/>
      </geometry>
    </collision>
    <inertial>
      <mass value="1"/>
      <inertia ixx="0.04" ixy="0.00" ixz="0.00" iyy="0.04" iyz="0.00" izz="0.02"/>
    </inertial>
  </link>
  <joint name="right_wrist_spherical_1_joint" type="revolute">
    <parent link="right_forearm_link"/>
    <child link="right_wrist_spherical_1_link"/>
    <!--  <origin xyz="0 0.20725 0 " rpy="${wrist_spherical_1_joint_rpy}" /> -->
    <origin rpy="1.570796325 3.14159265 0" xyz="0 0.2073 -0.0114"/>
    <axis xyz="0 0 1"/>
    <limit effort="60000.8" lower="-3.14159265" upper="3.14159265" velocity="0.921533845"/>
    <dynamics damping="0.01" friction="0.0"/>
  </joint>
  <link name="right_wrist_spherical_1_link">
    <visual>
        <origin rpy="0 0 0" xyz="0 0 0"/>

      <geometry>
        <mesh filename="package://movo_description_drake/meshes/manipulation/jaco/collision/wrist_spherical_1.obj"/>
      </geometry>
    </visual>
    <collision name="right_wrist_spherical_1_link">
      <origin rpy="0 0 0" xyz="0 0 0"/>
      <geometry>
        <mesh filename="package://movo_description_drake/meshes/manipulation/jaco/collision/wrist_spherical_1.obj"/>
      </geometry>
    </collision>
    <inertial>
      <mass value="1"/>
      <inertia ixx="0.04" ixy="0.00" ixz="0.00" iyy="0.04" iyz="0.00" izz="0.02"/>
    </inertial>
  </link>

  <joint name="right_wrist_spherical_2_joint" type="revolute">
    <parent link="right_wrist_spherical_1_link"/>
    <child link="right_wrist_spherical_2_link"/>
    <origin rpy="-1.570796325 0 0" xyz="0 0 -0.10375 "/>
    <axis xyz="0 0 1"/>
    <limit effort="60000.8" lower="-2.78" upper="2.78" velocity="0.921533845"/>
    <dynamics damping="0.01" friction="0.0"/>
  </joint>
  <link name="right_wrist_spherical_2_link">
    <visual>
      <origin rpy="0 0 0" xyz="0 0 0"/>

      <geometry>
        <mesh filename="package://movo_description_drake/meshes/manipulation/jaco/collision/wrist_spherical_2.obj"/>
      </geometry>
    </visual>
    <collision name="right_wrist_spherical_2_link">
      <origin rpy="0 0 0" xyz="0 0 0"/>
      <geometry>
        <mesh filename="package://movo_description_drake/meshes/manipulation/jaco/collision/wrist_spherical_2.obj"/>
      </geometry>
    </collision>
    <inertial>
      <mass value="1"/>
      <inertia ixx="0.04" ixy="0.00" ixz="0.00" iyy="0.04" iyz="0.00" izz="0.02"/>
    </inertial>
  </link>

  <joint name="right_wrist_3_joint" type="revolute">
    <parent link="right_wrist_spherical_2_link"/>
    <child link="right_wrist_3_link"/>
    <origin rpy="1.570796325 3.14159265 0" xyz="0 0.10375 0"/>
    <axis xyz="0 0 1"/>
    <limit effort="60000.8" lower="-3.14159265" upper="3.14159265" velocity="0.921533845"/>
    <dynamics damping="0.01" friction="0.0"/>
  </joint>
  <link name="right_wrist_3_link">
    <visual>
      <origin rpy="0 0 0" xyz="0 0 0"/>

      <geometry>
        <mesh filename="package://movo_description_drake/meshes/manipulation/jaco/collision/kinova_actuator_gearing.obj"/>
      </geometry>
    </visual>
    <collision name="right_wrist_3_link">
      <origin rpy="0 0 0" xyz="0 0 0"/>
      <geometry>
        <mesh filename="package://movo_description_drake/meshes/manipulation/jaco/collision/kinova_actuator_gearing.obj"/>
      </geometry>
    </collision>
    <inertial>
      <mass value="1"/>
      <inertia ixx="0.04" ixy="0.00" ixz="0.00" iyy="0.04" iyz="0.00" izz="0.02"/>
    </inertial>
  </link>

  <joint name="right_ee_fixed_joint" type="fixed">
    <parent link="right_wrist_3_link"/>
    <child link="right_ee_link"/>
    <origin rpy="3.14159265 1.570796325 0" xyz="0 0 -0.1600"/>
  </joint>
  <link name="right_ee_link">
    <inertial>
      <mass value="1"/>
      <inertia ixx="0.04" ixy="0.00" ixz="0.00" iyy="0.04" iyz="0.00" izz="0.02"/>
    </inertial>
  </link>
  <!-- Modification -->
  <joint name="right_tool_fixed_joint" type="fixed">
    <parent link="right_ee_link"/>
    <child link="right_tool_link"/>
    <origin rpy="1.570796325 0 1.570796325" xyz="0.02 0 0"/>
  </joint>
  <link name="right_tool_link">
    <inertial>
      <mass value="1"/>
      <inertia ixx="0.04" ixy="0.00" ixz="0.00" iyy="0.04" iyz="0.00" izz="0.02"/>
    </inertial>
  </link>
  <transmission name="right_shoulder_pan_trans">
    <type>transmission_interface/SimpleTransmission</type>
    <joint name="right_shoulder_pan_joint">
      <hardwareInterface>PositionJointInterface</hardwareInterface>
    </joint>
    <actuator name="right_shoulder_pan_motor">
      <mechanicalReduction>1</mechanicalReduction>
    </actuator>
  </transmission>
  <transmission name="right_shoulder_lift_trans">
    <type>transmission_interface/SimpleTransmission</type>
    <joint name="right_shoulder_lift_joint">
      <hardwareInterface>PositionJointInterface</hardwareInterface>
    </joint>
    <actuator name="right_shoulder_lift_motor">
      <mechanicalReduction>1</mechanicalReduction>
    </actuator>
  </transmission>
  <transmission name="right_half_arm_trans">
    <type>transmission_interface/SimpleTransmission</type>
    <joint name="right_arm_half_joint">
      <hardwareInterface>PositionJointInterface</hardwareInterface>
    </joint>
    <actuator name="right_arm_half_motor">
      <mechanicalReduction>1</mechanicalReduction>
    </actuator>
  </transmission>
  <transmission name="right_elbow_trans">
    <type>transmission_interface/SimpleTransmission</type>
    <joint name="right_elbow_joint">
      <hardwareInterface>PositionJointInterface</hardwareInterface>
    </joint>
    <actuator name="right_elbow_motor">
      <mechanicalReduction>1</mechanicalReduction>
    </actuator>
  </transmission>
  <transmission name="right_wrist_spherical_1_trans">
    <type>transmission_interface/SimpleTransmission</type>
    <joint name="right_wrist_spherical_1_joint">
      <hardwareInterface>PositionJointInterface</hardwareInterface>
    </joint>
    <actuator name="right_wrist_spherical_1_motor">
      <mechanicalReduction>1</mechanicalReduction>
    </actuator>
  </transmission>
  <transmission name="right_wrist_spherical_2_trans">
    <type>transmission_interface/SimpleTransmission</type>
    <joint name="right_wrist_spherical_2_joint">
      <hardwareInterface>PositionJointInterface</hardwareInterface>
    </joint>
    <actuator name="right_wrist_spherical_2_motor">
      <mechanicalReduction>1</mechanicalReduction>
    </actuator>
  </transmission>
  <transmission name="right_wrist_3_trans">
    <type>transmission_interface/SimpleTransmission</type>
    <joint name="right_wrist_3_joint">
      <hardwareInterface>PositionJointInterface</hardwareInterface>
    </joint>
    <actuator name="right_wrist_3_motor">
      <mechanicalReduction>1</mechanicalReduction>
    </actuator>
  </transmission>
  <joint name="left_kinova_joint" type="fixed">
    <parent link="linear_actuator_link"/>
    <child link="left_base_link"/>
    <origin rpy="-1.570796325 0 -1.570796325" xyz="0.0261046 0.13335 0.2799937"/>
  </joint>
  <link name="left_base_link">
    <visual>
        <origin rpy="0 0 0" xyz="0 0 0"/>

      <geometry>
        <mesh filename="package://movo_description_drake/meshes/manipulation/jaco/collision/base.obj"/>
      </geometry>
    </visual>
    <collision name="left_base_link">
      <origin rpy="0 0 0" xyz="0 0 0"/>

      <geometry>
        <mesh filename="package://movo_description_drake/meshes/manipulation/jaco/collision/base.obj"/>
      </geometry>
    </collision>
    <inertial>
      <mass value="1"/>
      <inertia ixx="0.04" ixy="0.00" ixz="0.00" iyy="0.04" iyz="0.00" izz="0.02"/>
    </inertial>
  </link>

  <joint name="left_shoulder_pan_joint" type="revolute">
    <parent link="left_base_link"/>
    <child link="left_shoulder_link"/>
    <origin rpy="0 3.14159265 0" xyz="0 0 0.0625"/>
    <axis xyz="0 0 1"/>
    <limit effort="18000.0" lower="-3.14159265" upper="3.14159265" velocity="0.691150384"/>
    <dynamics damping="0.01" friction="0.0"/>
  </joint>
  <link name="left_shoulder_link">
    <visual>
          <origin rpy="0 0 0" xyz="0 0 0"/>

      <geometry>
        <mesh filename="package://movo_description_drake/meshes/manipulation/jaco/collision/shoulder_7dof.obj"/>
      </geometry>
    </visual>
    <collision name="left_shoulder_link">
      <origin rpy="0 0 0" xyz="0 0 0"/>
      <geometry>
        <mesh filename="package://movo_description_drake/meshes/manipulation/jaco/collision/shoulder_7dof.obj"/>
      </geometry>
    </collision>
    <inertial>
      <mass value="1"/>
      <inertia ixx="0.04" ixy="0.00" ixz="0.00" iyy="0.04" iyz="0.00" izz="0.02"/>
    </inertial>
  </link>

  <joint name="left_shoulder_lift_joint" type="revolute">
    <parent link="left_shoulder_link"/>
    <child link="left_arm_half_1_link"/>
    <origin rpy="1.570796325 0 0" xyz="0 0 -0.11875"/>
    <axis xyz="0 0 1"/>
    <limit effort="30000.5" lower="-2.238" upper="2.238" velocity="0.691150384"/>
    <dynamics damping="0.01" friction="0.0"/>
  </joint>
  <link name="left_arm_half_1_link">
    <visual>
          <origin rpy="0 0 0" xyz="0 0 0"/>

      <geometry>
        <mesh filename="package://movo_description_drake/meshes/manipulation/jaco/collision/arm_half_1.obj"/>
      </geometry>
    </visual>
    <collision name="left_arm_half_1_link">
      <origin rpy="0 0 0" xyz="0 0 0"/>
      <geometry>
        <mesh filename="package://movo_description_drake/meshes/manipulation/jaco/collision/arm_half_1.obj"/>
      </geometry>
    </collision>
    <inertial>
      <mass value="1"/>
      <inertia ixx="0.04" ixy="0.00" ixz="0.00" iyy="0.04" iyz="0.00" izz="0.02"/>
    </inertial>
  </link>

  <joint name="left_arm_half_joint" type="revolute">
    <parent link="left_arm_half_1_link"/>
    <child link="left_arm_half_2_link"/>
    <origin rpy="-1.570796325 0 0" xyz="0 -0.205 0"/>
    <axis xyz="0 0 1"/>
    <limit effort="30000.5" lower="-3.14159265" upper="3.14159265" velocity="0.691150384"/>
    <dynamics damping="0.01" friction="0.0"/>
  </joint>
  <link name="left_arm_half_2_link">
    <visual>
          <origin rpy="0 0 0" xyz="0 0 0"/>

      <geometry>
        <mesh filename="package://movo_description_drake/meshes/manipulation/jaco/collision/arm_half_2.obj"/>
      </geometry>
    </visual>
    <collision name="left_arm_half_2_link">
      <origin rpy="0 0 0" xyz="0 0 0"/>

      <geometry>
        <mesh filename="package://movo_description_drake/meshes/manipulation/jaco/collision/arm_half_2.obj"/>
      </geometry>
    </collision>
    <inertial>
      <mass value="1"/>
      <inertia ixx="0.04" ixy="0.00" ixz="0.00" iyy="0.04" iyz="0.00" izz="0.02"/>
    </inertial>
  </link>

  <joint name="left_elbow_joint" type="revolute">
    <parent link="left_arm_half_2_link"/>
    <child link="left_forearm_link"/>
    <origin rpy="-1.570796325 0 0" xyz="0 0 -0.205"/>
    <axis xyz="0 0 1"/>
    <limit effort="18000.0" lower="-2.809" upper="2.809" velocity="0.691150384"/>
    <dynamics damping="0.01" friction="0.0"/>
  </joint>
  <link name="left_forearm_link">
    <visual>
          <origin rpy="0 0 0" xyz="0 0 0"/>

      <geometry>
        <mesh filename="package://movo_description_drake/meshes/manipulation/jaco/collision/forearm_7dof.obj"/>
      </geometry>
    </visual>
    <collision name="left_forearm_link">
      <origin rpy="0 0 0" xyz="0 0 0"/>

      <geometry>
        <mesh filename="package://movo_description_drake/meshes/manipulation/jaco/collision/forearm_7dof.obj"/>
      </geometry>
    </collision>
    <inertial>
      <mass value="1"/>
      <inertia ixx="0.04" ixy="0.00" ixz="0.00" iyy="0.04" iyz="0.00" izz="0.02"/>
    </inertial>
  </link>
  <joint name="left_wrist_spherical_1_joint" type="revolute">
    <parent link="left_forearm_link"/>
    <child link="left_wrist_spherical_1_link"/>
    <!--  <origin xyz="0 0.20725 0 " rpy="${wrist_spherical_1_joint_rpy}" /> -->
    <origin rpy="1.570796325 3.14159265 0" xyz="0 0.2073 -0.0114"/>
    <axis xyz="0 0 1"/>
    <limit effort="60000.8" lower="-3.14159265" upper="3.14159265" velocity="0.921533845"/>
    <dynamics damping="0.01" friction="0.0"/>
  </joint>
  <link name="left_wrist_spherical_1_link">
    <visual>
          <origin rpy="0 0 0" xyz="0 0 0"/>

      <geometry>
        <mesh filename="package://movo_description_drake/meshes/manipulation/jaco/collision/wrist_spherical_1.obj"/>
      </geometry>
    </visual>
    <collision name="left_wrist_spherical_1_link">
      <origin rpy="0 0 0" xyz="0 0 0"/>

      <geometry>
        <mesh filename="package://movo_description_drake/meshes/manipulation/jaco/collision/wrist_spherical_1.obj"/>
      </geometry>
    </collision>
    <inertial>
      <mass value="1"/>
      <inertia ixx="0.04" ixy="0.00" ixz="0.00" iyy="0.04" iyz="0.00" izz="0.02"/>
    </inertial>
  </link>

  <joint name="left_wrist_spherical_2_joint" type="revolute">
    <parent link="left_wrist_spherical_1_link"/>
    <child link="left_wrist_spherical_2_link"/>
    <origin rpy="-1.570796325 0 0" xyz="0 0 -0.10375 "/>
    <axis xyz="0 0 1"/>
    <limit effort="60000.8" lower="-2.78" upper="2.78" velocity="0.921533845"/>
    <dynamics damping="0.01" friction="0.0"/>
  </joint>
  <link name="left_wrist_spherical_2_link">
    <visual>
        <origin rpy="0 0 0" xyz="0 0 0"/>

      <geometry>
        <mesh filename="package://movo_description_drake/meshes/manipulation/jaco/collision/wrist_spherical_2.obj"/>
      </geometry>
    </visual>
    <collision name="left_wrist_spherical_2_link">
      <origin rpy="0 0 0" xyz="0 0 0"/>
      <geometry>
        <mesh filename="package://movo_description_drake/meshes/manipulation/jaco/collision/wrist_spherical_2.obj"/>
      </geometry>
    </collision>
    <inertial>
      <mass value="1"/>
      <inertia ixx="0.04" ixy="0.00" ixz="0.00" iyy="0.04" iyz="0.00" izz="0.02"/>
    </inertial>
  </link>

  <joint name="left_wrist_3_joint" type="revolute">
    <parent link="left_wrist_spherical_2_link"/>
    <child link="left_wrist_3_link"/>
    <origin rpy="1.570796325 3.14159265 0" xyz="0 0.10375 0"/>
    <axis xyz="0 0 1"/>
    <limit effort="60000.8" lower="-3.14159265" upper="3.14159265" velocity="0.921533845"/>
    <dynamics damping="0.01" friction="0.0"/>
  </joint>
  <link name="left_wrist_3_link">
    <visual>
      <origin rpy="0 0 0" xyz="0 0 0"/>

      <geometry>
        <mesh filename="package://movo_description_drake/meshes/manipulation/jaco/collision/kinova_actuator_gearing.obj"/>
      </geometry>
    </visual>
    <collision name="left_wrist_3_link">
      <origin rpy="0 0 0" xyz="0 0 0"/>

      <geometry>
        <mesh filename="package://movo_description_drake/meshes/manipulation/jaco/collision/kinova_actuator_gearing.obj"/>
      </geometry>
    </collision>
    <inertial>
      <mass value="1"/>
      <inertia ixx="0.04" ixy="0.00" ixz="0.00" iyy="0.04" iyz="0.00" izz="0.02"/>
    </inertial>
  </link>

  <joint name="left_ee_fixed_joint" type="fixed">
    <parent link="left_wrist_3_link"/>
    <child link="left_ee_link"/>
    <origin rpy="3.14159265 1.570796325 0" xyz="0 0 -0.1600"/>
  </joint>
  <link name="left_ee_link">
    <inertial>
      <mass value="1"/>
      <inertia ixx="0.04" ixy="0.00" ixz="0.00" iyy="0.04" iyz="0.00" izz="0.02"/>
    </inertial>
  </link>
  <!-- Modification -->
  <joint name="left_tool_fixed_joint" type="fixed">
    <parent link="left_ee_link"/>
    <child link="left_tool_link"/>
    <origin rpy="1.570796325 0 1.570796325" xyz="0 0 0"/>
  </joint>
  <link name="left_tool_link">
    <inertial>
      <mass value="1"/>
      <inertia ixx="0.04" ixy="0.00" ixz="0.00" iyy="0.04" iyz="0.00" izz="0.02"/>
    </inertial>
  </link>
  <transmission name="left_shoulder_pan_trans">
    <type>transmission_interface/SimpleTransmission</type>
    <joint name="left_shoulder_pan_joint">
      <hardwareInterface>PositionJointInterface</hardwareInterface>
    </joint>
    <actuator name="left_shoulder_pan_motor">
      <mechanicalReduction>1</mechanicalReduction>
    </actuator>
  </transmission>
  <transmission name="left_shoulder_lift_trans">
    <type>transmission_interface/SimpleTransmission</type>
    <joint name="left_shoulder_lift_joint">
      <hardwareInterface>PositionJointInterface</hardwareInterface>
    </joint>
    <actuator name="left_shoulder_lift_motor">
      <mechanicalReduction>1</mechanicalReduction>
    </actuator>
  </transmission>
  <transmission name="left_half_arm_trans">
    <type>transmission_interface/SimpleTransmission</type>
    <joint name="left_arm_half_joint">
      <hardwareInterface>PositionJointInterface</hardwareInterface>
    </joint>
    <actuator name="left_arm_half_motor">
      <mechanicalReduction>1</mechanicalReduction>
    </actuator>
  </transmission>
  <transmission name="left_elbow_trans">
    <type>transmission_interface/SimpleTransmission</type>
    <joint name="left_elbow_joint">
      <hardwareInterface>PositionJointInterface</hardwareInterface>
    </joint>
    <actuator name="left_elbow_motor">
      <mechanicalReduction>1</mechanicalReduction>
    </actuator>
  </transmission>
  <transmission name="left_wrist_spherical_1_trans">
    <type>transmission_interface/SimpleTransmission</type>
    <joint name="left_wrist_spherical_1_joint">
      <hardwareInterface>PositionJointInterface</hardwareInterface>
    </joint>
    <actuator name="left_wrist_spherical_1_motor">
      <mechanicalReduction>1</mechanicalReduction>
    </actuator>
  </transmission>
  <transmission name="left_wrist_spherical_2_trans">
    <type>transmission_interface/SimpleTransmission</type>
    <joint name="left_wrist_spherical_2_joint">
      <hardwareInterface>PositionJointInterface</hardwareInterface>
    </joint>
    <actuator name="left_wrist_spherical_2_motor">
      <mechanicalReduction>1</mechanicalReduction>
    </actuator>
  </transmission>
  <transmission name="left_wrist_3_trans">
    <type>transmission_interface/SimpleTransmission</type>
    <joint name="left_wrist_3_joint">
      <hardwareInterface>PositionJointInterface</hardwareInterface>
    </joint>
    <actuator name="left_wrist_3_motor">
      <mechanicalReduction>1</mechanicalReduction>
    </actuator>
  </transmission>
  <joint name="right_kinova_robotiq_coupler_joint" type="fixed">
    <parent link="right_ee_link"/>
    <child link="right_robotiq_coupler_link"/>
    <origin rpy="-3.14159265 1.570796325 0" xyz="-0.16 0 0"/>
  </joint>
  <link name="right_robotiq_coupler_link">
    <visual>
        <origin rpy="0 0 0" xyz="0 0 0"/>

      <geometry>
        <mesh filename="package://movo_description_drake/meshes/manipulation/robotiq/collision/kinova_robotiq_coupler.obj"/>
      </geometry>
    </visual>
    <collision name="right_robotiq_coupler_link">
      <origin rpy="0 0 0" xyz="0 0 0"/>

      <geometry>
        <mesh filename="package://movo_description_drake/meshes/manipulation/robotiq/collision/kinova_robotiq_coupler.obj"/>
      </geometry>
    </collision>
    <inertial>
      <mass value="1"/>
      <inertia ixx="0.04" ixy="0.00" ixz="0.00" iyy="0.04" iyz="0.00" izz="0.02"/>
    </inertial>
  </link>

  <joint name="right_gripper_base_joint" type="fixed">
    <parent link="right_robotiq_coupler_link"/>
    <child link="right_gripper_base_link"/>
    <origin rpy="-1.570796325 1.570796325 0.0" xyz="0 0 -0.05105"/>
  </joint>
  <link name="right_gripper_base_link">
    <visual>
      <origin rpy="0 0 0" xyz="0 0 0"/>

      <geometry>
        <mesh filename="package://movo_description_drake/meshes/manipulation/robotiq/collision/robotiq_85_base_link.obj"/>
      </geometry>
    </visual>
    <collision name="right_gripper_base_link">
      <origin rpy="0 0 0" xyz="0 0 0"/>
      <geometry>
        <mesh filename="package://movo_description_drake/meshes/manipulation/robotiq/collision/robotiq_85_base_link.obj"/>
      </geometry>
    </collision>
    <inertial>
      <mass value="1"/>
      <inertia ixx="0.04" ixy="0.00" ixz="0.00" iyy="0.04" iyz="0.00" izz="0.02"/>
    </inertial>
  </link>

  <joint name="right_gripper_finger1_joint" type="revolute">
    <parent link="right_gripper_base_link"/>
    <child link="right_gripper_finger1_knuckle_link"/>
    <axis xyz="0 0 1"/>
    <origin rpy="3.14159265 0.0 0.0" xyz="0.05490451627 0.03060114443 0.0"/>
    <limit effort="1000" lower="0.0" upper="0.804" velocity="2.0"/>
  </joint>
  <joint name="right_gripper_finger2_joint" type="revolute">
    <parent link="right_gripper_base_link"/>
    <child link="right_gripper_finger2_knuckle_link"/>
    <axis xyz="0 0 1"/>
    <origin rpy="0.0 0.0 0.0" xyz="0.05490451627 -0.03060114443 0.0"/>
    <limit effort="1000" lower="-3.14" upper="3.14" velocity="100.0"/>
    <mimic joint="right_gripper_finger1_joint"/>
  </joint>
  <link name="right_gripper_finger1_knuckle_link">
    <visual>
      <origin rpy="0 0 0" xyz="0 0 0"/>

      <geometry>
        <mesh filename="package://movo_description_drake/meshes/manipulation/robotiq/collision/robotiq_85_knuckle_link.obj"/>
      </geometry>
    </visual>
    <collision name="right_gripper_finger1_knuckle_link">
      <origin rpy="0 0 0" xyz="0 0 0"/>

      <geometry>
        <mesh filename="package://movo_description_drake/meshes/manipulation/robotiq/collision/robotiq_85_knuckle_link.obj"/>
      </geometry>
    </collision>
    <inertial>
      <mass value="1"/>
      <inertia ixx="0.04" ixy="0.00" ixz="0.00" iyy="0.04" iyz="0.00" izz="0.02"/>
    </inertial>
  </link>

  <link name="right_gripper_finger2_knuckle_link">
    <visual>
      <origin rpy="0 0 0" xyz="0 0 0"/>

      <geometry>
        <mesh filename="package://movo_description_drake/meshes/manipulation/robotiq/collision/robotiq_85_knuckle_link.obj"/>
      </geometry>
    </visual>
    <collision name="right_gripper_finger2_knuckle_link">
      <origin rpy="0 0 0" xyz="0 0 0"/>

      <geometry>
        <mesh filename="package://movo_description_drake/meshes/manipulation/robotiq/collision/robotiq_85_knuckle_link.obj"/>
      </geometry>
    </collision>
    <inertial>
      <mass value="1"/>
      <inertia ixx="0.04" ixy="0.00" ixz="0.00" iyy="0.04" iyz="0.00" izz="0.02"/>
    </inertial>
  </link>

  <joint name="right_gripper_finger1_finger_joint" type="fixed">
    <parent link="right_gripper_finger1_knuckle_link"/>
    <child link="right_gripper_finger1_finger_link"/>
    <origin rpy="0 0 0" xyz="-0.00408552455 -0.03148604435 0.0"/>
  </joint>
  <joint name="right_gripper_finger2_finger_joint" type="fixed">
    <parent link="right_gripper_finger2_knuckle_link"/>
    <child link="right_gripper_finger2_finger_link"/>
    <origin rpy="0 0 0" xyz="-0.00408552455 -0.03148604435 0.0"/>
  </joint>
  <link name="right_gripper_finger1_finger_link">
    <visual>
      <origin rpy="0 0 0" xyz="0 0 0"/>

      <geometry>
        <mesh filename="package://movo_description_drake/meshes/manipulation/robotiq/collision/robotiq_85_finger_link.obj"/>
      </geometry>
    </visual>
    <collision name="right_gripper_finger1_finger_link">
      <origin rpy="0 0 0" xyz="0 0 0"/>

      <geometry>
        <mesh filename="package://movo_description_drake/meshes/manipulation/robotiq/collision/robotiq_85_finger_link.obj"/>
      </geometry>
    </collision>
    <inertial>
      <mass value="1"/>
      <inertia ixx="0.04" ixy="0.00" ixz="0.00" iyy="0.04" iyz="0.00" izz="0.02"/>
    </inertial>
  </link>

  <link name="right_gripper_finger2_finger_link">
    <visual>
      <origin rpy="0 0 0" xyz="0 0 0"/>

      <geometry>
        <mesh filename="package://movo_description_drake/meshes/manipulation/robotiq/collision/robotiq_85_finger_link.obj"/>
      </geometry>
    </visual>
    <collision name="right_gripper_finger2_finger_link">
      <origin rpy="0 0 0" xyz="0 0 0"/>

      <geometry>
        <mesh filename="package://movo_description_drake/meshes/manipulation/robotiq/collision/robotiq_85_finger_link.obj"/>
      </geometry>
    </collision>
    <inertial>
      <mass value="1"/>
      <inertia ixx="0.04" ixy="0.00" ixz="0.00" iyy="0.04" iyz="0.00" izz="0.02"/>
    </inertial>
  </link>

  <joint name="right_gripper_finger1_inner_knuckle_joint" type="continuous">
    <parent link="right_gripper_base_link"/>
    <child link="right_gripper_finger1_inner_knuckle_link"/>
    <axis xyz="0 0 1"/>
    <origin rpy="3.14159265 0.0 0.0" xyz="0.06142 0.0127 0"/>
    <limit effort="0.1" lower="-3.14" upper="3.14" velocity="100.0"/>
    <mimic joint="right_gripper_finger1_joint" offset="0"/>
  </joint>
  <joint name="right_gripper_finger2_inner_knuckle_joint" type="continuous">
    <parent link="right_gripper_base_link"/>
    <child link="right_gripper_finger2_inner_knuckle_link"/>
    <axis xyz="0 0 1"/>
    <origin rpy="0 0 0" xyz="0.06142 -0.0127 0"/>
    <limit effort="0.1" lower="-3.14" upper="3.14" velocity="100.0"/>
    <mimic joint="right_gripper_finger1_joint" offset="0"/>
  </joint>
  <link name="right_gripper_finger1_inner_knuckle_link">
    <visual>
      <origin rpy="0 0 0" xyz="0 0 0"/>

      <geometry>
        <mesh filename="package://movo_description_drake/meshes/manipulation/robotiq/collision/robotiq_85_inner_knuckle_link.obj"/>
      </geometry>
    </visual>
    <collision name="right_gripper_finger1_inner_knuckle_link">
      <origin rpy="0 0 0" xyz="0 0 0"/>

      <geometry>
        <mesh filename="package://movo_description_drake/meshes/manipulation/robotiq/collision/robotiq_85_inner_knuckle_link.obj"/>
      </geometry>
    </collision>
    <inertial>
      <mass value="1"/>
      <inertia ixx="0.04" ixy="0.00" ixz="0.00" iyy="0.04" iyz="0.00" izz="0.02"/>
    </inertial>
  </link>

  <link name="right_gripper_finger2_inner_knuckle_link">
    <visual>
      <origin rpy="0 0 0" xyz="0 0 0"/>

      <geometry>
        <mesh filename="package://movo_description_drake/meshes/manipulation/robotiq/collision/robotiq_85_inner_knuckle_link.obj"/>
      </geometry>
    </visual>
    <collision name="right_gripper_finger2_inner_knuckle_link">

      <origin rpy="0 0 0" xyz="0 0 0"/>

      <geometry>
        <mesh filename="package://movo_description_drake/meshes/manipulation/robotiq/collision/robotiq_85_inner_knuckle_link.obj"/>
      </geometry>
    </collision>
    <inertial>
      <mass value="1"/>
      <inertia ixx="0.04" ixy="0.00" ixz="0.00" iyy="0.04" iyz="0.00" izz="0.02"/>
    </inertial>
  </link>

  <joint name="right_gripper_finger1_finger_tip_joint" type="continuous">
    <parent link="right_gripper_finger1_inner_knuckle_link"/>
    <child link="right_gripper_finger1_finger_tip_link"/>
    <axis xyz="0 0 1"/>
    <origin rpy="0.0 0.0 0.0" xyz="0.04303959807 -0.03759940821 0.0"/>
    <limit effort="0.1" lower="-3.14" upper="3.14" velocity="100.0"/>
    <mimic joint="right_gripper_finger1_joint" multiplier="-1"/>
  </joint>
  <joint name="right_gripper_finger2_finger_tip_joint" type="continuous">
    <parent link="right_gripper_finger2_inner_knuckle_link"/>
    <child link="right_gripper_finger2_finger_tip_link"/>
    <axis xyz="0 0 1"/>
    <origin rpy="0.0 0.0 0.0" xyz="0.04303959807 -0.03759940821  0.0"/>
    <limit effort="0.1" lower="-3.14" upper="3.14" velocity="100.0"/>
    <mimic joint="right_gripper_finger1_joint" multiplier="-1"/>
  </joint>
  <link name="right_gripper_finger1_finger_tip_link">
    <visual>
      <origin rpy="0 0 0" xyz="0 0 0"/>

      <geometry>
        <mesh filename="package://movo_description_drake/meshes/manipulation/robotiq/collision/robotiq_85_finger_tip_link.obj"/>
      </geometry>
    </visual>
    <collision name="right_gripper_finger1_finger_tip_link">
      <origin rpy="0 0 0" xyz="0 0 0"/>

      <geometry>
        <mesh filename="package://movo_description_drake/meshes/manipulation/robotiq/collision/robotiq_85_finger_tip_link.obj"/>
      </geometry>
    </collision>
    <inertial>
      <mass value="1"/>
      <inertia ixx="0.04" ixy="0.00" ixz="0.00" iyy="0.04" iyz="0.00" izz="0.02"/>
    </inertial>
  </link>

  <link name="right_gripper_finger2_finger_tip_link">
    <visual>
      <origin rpy="0 0 0" xyz="0 0 0"/>

      <geometry>
        <mesh filename="package://movo_description_drake/meshes/manipulation/robotiq/collision/robotiq_85_finger_tip_link.obj"/>
      </geometry>
    </visual>
    <collision name="right_gripper_finger2_finger_tip_link">
      <origin rpy="0 0 0" xyz="0 0 0"/>

      <geometry>
        <mesh filename="package://movo_description_drake/meshes/manipulation/robotiq/collision/robotiq_85_finger_tip_link.obj"/>
      </geometry>
    </collision>
    <inertial>
      <mass value="1"/>
      <inertia ixx="0.04" ixy="0.00" ixz="0.00" iyy="0.04" iyz="0.00" izz="0.02"/>
    </inertial>
  </link>

  <transmission name="right_gripper_finger1_trans">
    <type>transmission_interface/SimpleTransmission</type>
    <joint name="right_gripper_finger1_joint">
      <hardwareInterface>PositionJointInterface</hardwareInterface>
    </joint>
    <actuator name="right_gripper_finger1_motor">
      <mechanicalReduction>1</mechanicalReduction>
      <hardwareInterface>PositionJointInterface</hardwareInterface>
    </actuator>
  </transmission>

  <joint name="left_gripper_base_joint" type="fixed">
    <parent link="left_ee_link"/>
    <child link="left_gripper_base_link"/>
    <origin rpy="-3.14159265 1.570796325 0" xyz="-0.16 0 0"/>
  </joint>
  <link name="left_gripper_base_link">
    <visual>
      <origin rpy="0 0 0" xyz="0 0 0"/>

      <geometry>
        <mesh filename="package://movo_description_drake/meshes/manipulation/kinova_grippers/collision/kg3_base_link.obj"/>
      </geometry>
    </visual>
    <collision name="left_gripper_base_link">
      <origin rpy="0 0 0" xyz="0 0 0"/>

      <geometry>
        <mesh filename="package://movo_description_drake/meshes/manipulation/kinova_grippers/collision/kg3_base_link.obj"/>
      </geometry>
    </collision>
    <inertial>
      <mass value="1"/>
      <inertia ixx="0.04" ixy="0.00" ixz="0.00" iyy="0.04" iyz="0.00" izz="0.02"/>
    </inertial>
  </link>

  <joint name="left_gripper_finger1_joint" type="revolute">
    <parent link="left_gripper_base_link"/>
    <child link="left_gripper_finger1_knuckle_link"/>
    <axis xyz="0 0 1"/>
    <origin rpy="1.4676 -0.0092813 -1.7501" xyz="-0.0027954 0.031318 -0.11464"/>
    <limit damping="0.005" effort="3.0" friction="0.005" lower="0.0" upper="0.986111027" velocity="1.0"/>
  </joint>
  <link name="left_gripper_finger1_knuckle_link">
    <visual>
      <origin rpy="0 0 0" xyz="0 0 0"/>

      <geometry>
        <mesh filename="package://movo_description_drake/meshes/manipulation/kinova_grippers/collision/finger_knuckle.obj"/>
      </geometry>
    </visual>
    <collision name="left_gripper_finger1_knuckle_link">
      <origin rpy="0 0 0" xyz="0 0 0"/>

      <geometry>
        <mesh filename="package://movo_description_drake/meshes/manipulation/kinova_grippers/collision/finger_knuckle.obj"/>
      </geometry>
    </collision>
    <inertial>
      <mass value="1"/>
      <inertia ixx="0.04" ixy="0.00" ixz="0.00" iyy="0.04" iyz="0.00" izz="0.02"/>
    </inertial>
  </link>

  <joint name="left_gripper_finger2_joint" type="revolute">
    <parent link="left_gripper_base_link"/>
    <child link="left_gripper_finger2_knuckle_link"/>
    <axis xyz="0 0 1"/>
    <origin rpy="1.570796325 0 1.7555" xyz="0.022289 -0.027253 -0.11471"/>
    <limit damping="0.005" effort="3.0" friction="0.005" lower="0.0" upper="0.986111027" velocity="1.0"/>
    <mimic joint="left_gripper_finger1_joint"/>
  </joint>
  <link name="left_gripper_finger2_knuckle_link">
    <visual>
      <origin rpy="0 0 0" xyz="0 0 0"/>

      <geometry>
        <mesh filename="package://movo_description_drake/meshes/manipulation/kinova_grippers/collision/finger_knuckle.obj"/>
      </geometry>
    </visual>
    <collision name="left_gripper_finger2_knuckle_link">
        <origin rpy="0 0 0" xyz="0 0 0"/>

      <geometry>
        <mesh filename="package://movo_description_drake/meshes/manipulation/kinova_grippers/collision/finger_knuckle.obj"/>
      </geometry>
    </collision>
    <inertial>
      <mass value="1"/>
      <inertia ixx="0.04" ixy="0.00" ixz="0.00" iyy="0.04" iyz="0.00" izz="0.02"/>
    </inertial>
  </link>

  <joint name="left_gripper_finger3_joint" type="revolute">
    <parent link="left_gripper_base_link"/>
    <child link="left_gripper_finger3_knuckle_link"/>
    <axis xyz="0 0 1"/>
    <origin rpy="1.570796325 0 1.3861" xyz="-0.022284 -0.027223 -0.11473"/>
    <limit damping="0.005" effort="3.0" friction="0.005" lower="0.0" upper="0.986111027" velocity="1.0"/>
    <mimic joint="left_gripper_finger1_joint"/>
  </joint>
  <link name="left_gripper_finger3_knuckle_link">
    <visual>
      <origin rpy="0 0 0" xyz="0 0 0"/>

      <geometry>
        <mesh filename="package://movo_description_drake/meshes/manipulation/kinova_grippers/collision/finger_knuckle.obj"/>
      </geometry>
    </visual>
    <collision name="left_gripper_finger3_knuckle_link">
          <origin rpy="0 0 0" xyz="0 0 0"/>

      <geometry>
        <mesh filename="package://movo_description_drake/meshes/manipulation/kinova_grippers/collision/finger_knuckle.obj"/>
      </geometry>
    </collision>
    <inertial>
      <mass value="1"/>
      <inertia ixx="0.04" ixy="0.00" ixz="0.00" iyy="0.04" iyz="0.00" izz="0.02"/>
    </inertial>
  </link>

  <joint name="left_gripper_finger1_finger_tip_joint" type="fixed">
    <parent link="left_gripper_finger1_knuckle_link"/>
    <child link="left_gripper_finger1_finger_tip_link"/>
    <origin rpy="0 0 0" xyz="-0.0245981 -0.036051 0.0"/>
  </joint>
  <link name="left_gripper_finger1_finger_tip_link">
    <visual>
      <origin rpy="0 0 0" xyz="0 0 0"/>

      <geometry>
        <mesh filename="package://movo_description_drake/meshes/manipulation/kinova_grippers/collision/finger_tip.obj"/>
      </geometry>
    </visual>
    <collision name="left_gripper_finger1_finger_tip_link">
      <origin rpy="0 0 0" xyz="0 0 0"/>

      <geometry>
        <mesh filename="package://movo_description_drake/meshes/manipulation/kinova_grippers/collision/finger_tip.obj"/>
      </geometry>
    </collision>
    <inertial>
      <mass value="1"/>
      <inertia ixx="0.04" ixy="0.00" ixz="0.00" iyy="0.04" iyz="0.00" izz="0.02"/>
    </inertial>
  </link>

  <joint name="left_gripper_finger2_finger_tip_joint" type="fixed">
    <parent link="left_gripper_finger2_knuckle_link"/>
    <child link="left_gripper_finger2_finger_tip_link"/>
    <origin rpy="0 0 0" xyz="-0.0245981 -0.036051 0.0"/>
  </joint>
  <link name="left_gripper_finger2_finger_tip_link">
    <visual>
      <origin rpy="0 0 0" xyz="0 0 0"/>

      <geometry>
        <mesh filename="package://movo_description_drake/meshes/manipulation/kinova_grippers/collision/finger_tip.obj"/>
      </geometry>
    </visual>
    <collision name="left_gripper_finger2_finger_tip_link">
      <origin rpy="0 0 0" xyz="0 0 0"/>

      <geometry>
        <mesh filename="package://movo_description_drake/meshes/manipulation/kinova_grippers/collision/finger_tip.obj"/>
      </geometry>
    </collision>
    <inertial>
      <mass value="1"/>
      <inertia ixx="0.04" ixy="0.00" ixz="0.00" iyy="0.04" iyz="0.00" izz="0.02"/>
    </inertial>
  </link>

  <joint name="left_gripper_finger3_finger_tip_joint" type="fixed">
    <parent link="left_gripper_finger3_knuckle_link"/>
    <child link="left_gripper_finger3_finger_tip_link"/>
    <origin rpy="0 0 0" xyz="-0.0245981 -0.036051 0.0"/>
  </joint>
  <link name="left_gripper_finger3_finger_tip_link">
    <visual>
      <origin rpy="0 0 0" xyz="0 0 0"/>

      <geometry>
        <mesh filename="package://movo_description_drake/meshes/manipulation/kinova_grippers/collision/finger_tip.obj"/>
      </geometry>
    </visual>
    <collision name="left_gripper_finger3_finger_tip_link">
      <origin rpy="0 0 0" xyz="0 0 0"/>

      <geometry>
        <mesh filename="package://movo_description_drake/meshes/manipulation/kinova_grippers/collision/finger_tip.obj"/>
      </geometry>
    </collision>
    <inertial>
      <mass value="1"/>
      <inertia ixx="0.04" ixy="0.00" ixz="0.00" iyy="0.04" iyz="0.00" izz="0.02"/>
    </inertial>
  </link>

  <transmission name="left_gripper_finger1_trans">
    <type>transmission_interface/SimpleTransmission</type>
    <joint name="left_gripper_finger1_joint">
      <hardwareInterface>EffortJointInterface</hardwareInterface>
    </joint>
    <actuator name="left_gripper_finger1_motor">
      <mechanicalReduction>1</mechanicalReduction>
      <hardwareInterface>EffortJointInterface</hardwareInterface>
    </actuator>
  </transmission>

  <drake:collision_filter_group name="left_shoulder_link_linear_actuator_fixed_link">
    <drake:member link="left_shoulder_link" />
    <drake:member link="linear_actuator_fixed_link" />
    <drake:ignored_collision_filter_group name="left_shoulder_link_linear_actuator_fixed_link" />
  </drake:collision_filter_group>

  <drake:collision_filter_group name="left_shoulder_link_linear_actuator_link">
    <drake:member link="left_shoulder_link" />
    <drake:member link="linear_actuator_link" />
    <drake:ignored_collision_filter_group name="left_shoulder_link_linear_actuator_link" />
  </drake:collision_filter_group>

  <drake:collision_filter_group name="left_arm_half_1_link_linear_actuator_link">
    <drake:member link="left_arm_half_1_link" />
    <drake:member link="linear_actuator_link" />
    <drake:ignored_collision_filter_group name="left_arm_half_1_link_linear_actuator_link" />
  </drake:collision_filter_group>

  <drake:collision_filter_group name="left_wrist_spherical_2_link_left_gripper_base_link">
    <drake:member link="left_wrist_spherical_2_link" />
    <drake:member link="left_gripper_base_link" />
    <drake:ignored_collision_filter_group name="left_wrist_spherical_2_link_left_gripper_base_link" />
  </drake:collision_filter_group>

  <drake:collision_filter_group name="right_shoulder_link_linear_actuator_fixed_link">
    <drake:member link="right_shoulder_link" />
    <drake:member link="linear_actuator_fixed_link" />
    <drake:ignored_collision_filter_group name="right_shoulder_link_linear_actuator_fixed_link" />
  </drake:collision_filter_group>

  <drake:collision_filter_group name="right_shoulder_link_linear_actuator_link">
    <drake:member link="right_shoulder_link" />
    <drake:member link="linear_actuator_link" />
    <drake:ignored_collision_filter_group name="right_shoulder_link_linear_actuator_link" />
  </drake:collision_filter_group>

  <drake:collision_filter_group name="right_wrist_spherical_2_link_right_robotiq_coupler_link">
    <drake:member link="right_wrist_spherical_2_link" />
    <drake:member link="right_robotiq_coupler_link" />
    <drake:ignored_collision_filter_group name="right_wrist_spherical_2_link_right_robotiq_coupler_link" />
  </drake:collision_filter_group>

  <drake:collision_filter_group name="right_wrist_spherical_2_link_right_tool_link">
    <drake:member link="right_wrist_spherical_2_link" />
    <drake:member link="right_tool_link" />
    <drake:ignored_collision_filter_group name="right_wrist_spherical_2_link_right_tool_link" />
  </drake:collision_filter_group>

  <drake:collision_filter_group name="linear_actuator_fixed_link_front_laser_link">
    <drake:member link="linear_actuator_fixed_link" />
    <drake:member link="front_laser_link" />
    <drake:ignored_collision_filter_group name="linear_actuator_fixed_link_front_laser_link" />
  </drake:collision_filter_group>

  <drake:collision_filter_group name="linear_actuator_fixed_link_rear_laser_link">
    <drake:member link="linear_actuator_fixed_link" />
    <drake:member link="rear_laser_link" />
    <drake:ignored_collision_filter_group name="linear_actuator_fixed_link_rear_laser_link" />
  </drake:collision_filter_group>

  <drake:collision_filter_group name="linear_actuator_fixed_link_right_base_link">
    <drake:member link="linear_actuator_fixed_link" />
    <drake:member link="right_base_link" />
    <drake:ignored_collision_filter_group name="linear_actuator_fixed_link_right_base_link" />
  </drake:collision_filter_group>

  <drake:collision_filter_group name="linear_actuator_fixed_link_left_base_link">
    <drake:member link="linear_actuator_fixed_link" />
    <drake:member link="left_base_link" />
    <drake:ignored_collision_filter_group name="linear_actuator_fixed_link_left_base_link" />
  </drake:collision_filter_group>

  <drake:collision_filter_group name="right_wrist_3_link_right_robotiq_coupler_link">
    <drake:member link="right_wrist_3_link" />
    <drake:member link="right_robotiq_coupler_link" />
    <drake:ignored_collision_filter_group name="right_wrist_3_link_right_robotiq_coupler_link" />
  </drake:collision_filter_group>

  <drake:collision_filter_group name="right_wrist_3_link_right_gripper_base_link">
    <drake:member link="right_wrist_3_link" />
    <drake:member link="right_gripper_base_link" />
    <drake:ignored_collision_filter_group name="right_wrist_3_link_right_gripper_base_link" />
  </drake:collision_filter_group>

  <drake:collision_filter_group name="right_gripper_finger1_finger_link_right_gripper_finger1_finger_tip_link">
    <drake:member link="right_gripper_finger1_finger_link" />
    <drake:member link="right_gripper_finger1_finger_tip_link" />
    <drake:ignored_collision_filter_group name="right_gripper_finger1_finger_link_right_gripper_finger1_finger_tip_link" />
  </drake:collision_filter_group>

  <drake:collision_filter_group name="right_gripper_finger2_finger_link_right_gripper_finger2_finger_tip_link">
    <drake:member link="right_gripper_finger2_finger_link" />
    <drake:member link="right_gripper_finger2_finger_tip_link" />
    <drake:ignored_collision_filter_group name="right_gripper_finger2_finger_link_right_gripper_finger2_finger_tip_link" />
  </drake:collision_filter_group>

  <drake:collision_filter_group name="left_wrist_3_link_left_gripper_base_link">
    <drake:member link="left_wrist_3_link" />
    <drake:member link="left_gripper_base_link" />
    <drake:ignored_collision_filter_group name="left_wrist_3_link_left_gripper_base_link" />
  </drake:collision_filter_group>

</robot>