<?xml version="1.0" encoding="UTF-8"?>
<robot xmlns:xacro="http://www.ros.org/wiki/xacro" name="carter">
   <xacro:macro name="carter_robot">
      <material name="black">
         <color rgba=".1 .1 .1 1"/>
      </material>
      <material name="gray">
         <color rgba=".5 .5 .5 1"/>
      </material>
      <link name="chassis_link">
         <visual>
            <origin rpy="0 0 0" xyz="0 0 0" />
            <geometry>
               <mesh filename="package://carter/meshes/chassis_franka.obj" />
            </geometry>
            <material name="gray"/>
         </visual>
         <collision>
            <origin rpy="0 0 0" xyz="-0.07764248 -0.000000 0.14683718" />
            <geometry>
               <box size=".55 .40 .54"/>
            </geometry>
         </collision>
         <inertial>
            <origin rpy="0 0 0" xyz="0.000000 0.000000 0.000000" />
            <mass value="45.88" />
            <inertia ixx="1.182744" ixy="0.017957" ixz="-0.077476" iyx="0.017957" iyy="0.538664" iyz="0.000018" izx="-0.077476" izy="0.000018" izz="1.240229"/>
         </inertial>
      </link>
      <link name="left_wheel_link">
         <visual>
            <origin rpy="1.57057 -1.57057 0" xyz="0 0 0" />
            <geometry>
               <mesh filename="package://carter/meshes/side_wheel.obj" />
            </geometry>
            <material name="black"/>
         </visual>
         <collision>
            <origin rpy="1.57057 -1.57057 0" xyz="0 -0.05 0" />
            <geometry>
               <cylinder radius = "0.240" length = "0.1"/>
            </geometry>
         </collision>
         <inertial>
            <origin rpy="0 0 0" xyz="0.000000 0.000000 0.000000" />
            <mass value="4.195729" />
            <inertia ixx="0.063680" ixy="0.000000" ixz="0.000000" iyx="0.000000" iyy="0.121410" iyz="0.000000" izx="0.000000" izy="0.000000" izz="0.063680"/>
         </inertial>
      </link>
      <link name="right_wheel_link">
         <visual>
            <origin rpy="-1.57057 -1.57057 0" xyz="0 0 0" />
            <geometry>
               <mesh filename="package://carter/meshes/side_wheel.obj" />
            </geometry>
            <material name="black"/>
         </visual>
         <collision>
            <origin rpy="-1.57057 -1.57057 0" xyz="0 .05 0" />
            <geometry>
               <cylinder radius = "0.240" length = "0.1"/>
            </geometry>
         </collision>
         <inertial>
            <origin rpy="0 0 0" xyz="0.000000 0.000000 0.000000" />
            <mass value="4.195729" />
            <inertia ixx="0.063680" ixy="0.000000" ixz="0.000000" iyx="0.000000" iyy="0.121410" iyz="0.000000" izx="0.000000" izy="0.000000" izz="0.063680"/>
         </inertial>
      </link>
      <link name="rear_pivot_link">
         <visual>
            <origin rpy="-1.57057 0 0" xyz="-.03809695 0 -.088" />
            <geometry>
               <mesh filename="package://carter/meshes/pivot.obj" />
            </geometry>
            <material name="black"/>
         </visual>
         <collision>
            <origin rpy="0 0 0" xyz="-.01 0 -.03" />
            <geometry>
               <box size=".09 .08 .12"/>
            </geometry>
         </collision>
         <inertial>
            <origin rpy="0 0 0" xyz="0.000000 0.000000 0.000000" />
            <mass value="0.579519"/>
            <inertia ixx="0.001361" ixy="-0.000003" ixz="0.000347" iyx="-0.000003" iyy="0.001287" iyz="-0.000010" izx="0.000347" izy="-0.000010" izz="0.000632"/>
         </inertial>
      </link>
      <link name="rear_wheel_link">
         <visual>
            <origin rpy="1.57057 0 0" xyz="0 0 0" />
            <geometry>
               <mesh filename="package://carter/meshes/caster_wheel.obj" />
            </geometry>
         </visual>
         <collision>
            <origin rpy="1.57057 0 0" xyz="0 0 0" />
            <geometry>
               <cylinder radius=".076" length=".048" />
            </geometry>
         </collision>
         <inertial>
            <origin rpy="0 0 0" xyz="0.000000 0.000000 0.000000" />
            <mass value="1.25"/>
            <inertia ixx="0.001442" ixy="0.000000" ixz="0.000000" iyx="0.000000" iyy="0.002493" iyz="0.000000" izx="0.000000" izy="0.000000" izz="0.001442"/>
         </inertial>
      </link>
      <link name="front_pivot_link">
         <visual>
            <origin rpy="-1.57057 0 0" xyz="-.03809695 0 -.088" />
            <geometry>
               <mesh filename="package://carter/meshes/pivot.obj" />
            </geometry>
            <material name="black"/>
         </visual>
         <collision>
            <origin rpy="0 0 0" xyz="-.01 0 -.03" />
            <geometry>
               <box size=".09 .08 .12"/>
            </geometry>
         </collision>
         <inertial>
            <origin rpy="0 0 0" xyz="0.000000 0.000000 0.000000" />
            <mass value="0.579519"/>
            <inertia ixx="0.001361" ixy="-0.000003" ixz="0.000347" iyx="-0.000003" iyy="0.001287" iyz="-0.000010" izx="0.000347" izy="-0.000010" izz="0.000632"/>
         </inertial>
      </link>
      <link name="front_wheel_link">
         <visual>
            <origin rpy="1.57057 0 0" xyz="0 0 0" />
            <geometry>
               <mesh filename="package://carter/meshes/caster_wheel.obj" />
            </geometry>
         </visual>
         <collision>
            <origin rpy="1.57057 0 0" xyz="0 0 0" />
            <geometry>
               <cylinder radius=".076" length=".048" />
            </geometry>
         </collision>
         <inertial>
            <origin rpy="0 0 0" xyz="0.000000 0.000000 0.000000" />
            <mass value="1.25"/>
            <inertia ixx="0.001442" ixy="0.000000" ixz="0.000000" iyx="0.000000" iyy="0.002493" iyz="0.000000" izx="0.000000" izy="0.000000" izz="0.001442"/>
         </inertial>
      </link>
      <link name="com_offset">
         <visual>
            <origin rpy="0 0 0" xyz="-.23 0 .02" />
            <geometry>
               <box size="0.01 0.01 0.01"/>
            </geometry>
         </visual>
         <collision>
            <origin rpy="0 0 0" xyz="-.23 0 .02" />
            <geometry>
               <box size=".25 .25 .1"/>
            </geometry>
         </collision>
         <inertial>
            <origin rpy="0 0 0" xyz="0.000000 0.000000 0.000000" />
            <mass value="20.0" />
            <inertia ixx="1.208" ixy="0" ixz="0" iyy="1.208" iyz="0" izz="2.08" />
         </inertial>
      </link>
      <joint name="com_link" type="fixed">
         <origin rpy="0 0 0" xyz="0 0 0" />
         <axis xyz="0 1 0" />
         <parent link="chassis_link" />
         <child link="com_offset" />
      </joint>
      <link name="batteries_link">
         <visual>
            <origin rpy="0 0 0" xyz="0 0 0"/>
            <geometry>
               <box size=".01 .02 .02"/>
            </geometry>
            <material name="dark"/>
         </visual>
         <collision>
            <origin rpy="0 0 0" xyz="0 0 0"/>
            <geometry>
               <box size=".1 .3 .2"/>
            </geometry>
         </collision>
         <inertial>
            <origin rpy="0 0 0" xyz="0.000000 0.000000 0.000000"/>
            <mass value="20"/>
            <inertia ixx="0.216" ixy="0" ixz="0" iyx="0" iyy=".083" iyz="0" izx="0" izy="0" izz=".167"/>
         </inertial>
      </link>
      <joint name="batteries_joint" type="fixed">
         <origin xyz="0.31 0 0.09"/>
         <parent link="chassis_link"/>
         <child link="batteries_link"/>
      </joint>
      <joint name="left_wheel" type="continuous">
         <origin rpy="0 0 0" xyz="0 0.31420517 0" />
         <axis xyz="0 1 0" />
         <parent link="chassis_link" />
         <child link="left_wheel_link" />
      </joint>
      <joint name="right_wheel" type="continuous">
         <origin rpy="0 0 0" xyz="0 -0.31420517 0" />
         <axis xyz="0 1 0" />
         <parent link="chassis_link" />
         <child link="right_wheel_link" />
      </joint>
      <joint name="rear_pivot" type="continuous">
         <origin rpy="0 0 0" xyz="-0.31613607 0 -.0758" />
         <axis xyz="0 0 1" />
         <parent link="chassis_link" />
         <child link="rear_pivot_link" />
      </joint>
      <joint name="rear_axle" type="continuous">
         <origin rpy="0 0 0" xyz="-.03809695 0 -.088" />
         <axis xyz="0 1 0" />
         <parent link="rear_pivot_link" />
         <child link="rear_wheel_link" />
      </joint>
      <joint name="front_pivot" type="continuous">
         <origin rpy="0 0 0" xyz="0.31613607 0 -.0758" />
         <axis xyz="0 0 1" />
         <parent link="chassis_link" />
         <child link="front_pivot_link" />
      </joint>
      <joint name="front_axle" type="continuous">
         <origin rpy="0 0 0" xyz="-.03809695 0 -.088" />
         <axis xyz="0 1 0" />
         <parent link="front_pivot_link" />
         <child link="front_wheel_link" />
      </joint>
   </xacro:macro>
</robot>